Workbook

Sheet about_section
A1: SectionId | B1: Title | C1: Text | D1: JournalId | E1: JournalTitle | F1: journal
A2: 1757 | B2: Network Bioinformatics | C2: The Network Bioinformatics section is dedicated to publishing research focused on exploring and understanding complex biological pathways and interaction networks. Led by Dr. Patrick Aloy from the Institute for Research in Biomedicine, the Network Bioinformatics section welcomes submissions in various domains of network biology, which connect interdisciplinary approaches to advance the understanding of complex biological relationships. Topics considered in the scope of this section include: Submissions should provide detailed, in-depth knowledge about the development and/or application of methodologies for exploring and extracting relevant information from biological networks. The Network Bioinformatics section does not consider submissions that lack a strong focus on the integration of network-based approaches with bioinformatics. This multidisciplinary section is at the forefront of disseminating and communicating cutting-edge scientific knowledge and impactful discoveries in the field of network biology to researchers, industry, policymakers, and the public worldwide. | D2: 1722 | E2: Frontiers in Bioinformatics | F2: =VLOOKUP(D2,分野ID!$A$2:$B$49,2,FALSE) -> #N/A
A3: 2678 | B3: Imaging and Detection | C3: The Imaging and Detection section is dedicated to publishing research focused on advancing imaging and detection technologies for lab-on-chip applications. Led by Prof. Kevin Tsia from The University of Hong Kong, the Imaging and Detection section welcomes submissions in the various domains of imaging and detection, which connect interdisciplinary research and drive innovation in lab-on-chip technologies, for applications in the areas of environmental sciences, material sciences, biomedical and clinical sciences, and more. Topics considered in the scope of this section include: Submissions should provide detailed, in-depth knowledge about the development and application of imaging and detection technologies for lab-on-a-chip systems, imaging and detection computation, and emerging lab-on-a-chip imaging and detection applications. In particular, the section welcomes submissions which support and advance Sustainable Development Goals 3 (Good Health and Well-being), 9 (Industry, Innovation and Infrastructure), and 12 (Responsible Consumption and Production). This multidisciplinary section is at the forefront of disseminating and communicating cutting-edge scientific knowledge and impactful discoveries in the field of imaging and detection to researchers, industry, policymakers, and the public worldwide. | D3: 2670 | E3: Frontiers in Lab on a Chip Technologies | F3: =VLOOKUP(D3,分野ID!$A$2:$B$49,2,FALSE) -> #N/A
A4: 1883 | B4: Networks and Communications | C4: The Networks and Communications section is dedicated to publishing research focused on advancing the understanding of computer networks and communication channels. Led by Dr. Chintha Tellambura from the Department of Electrical and Computer Engineering at the University of Alberta and Dr. Theodoros Tsiftsis from the University of Thessaly, the Networks and Communications section welcomes submissions in the various domains of computer networking and communication, which connect theoretical principles with practical applications. Topics considered in the scope of this section include: Submissions should provide detailed, in-depth knowledge about the fundamentals and applications of computer networking and communication technologies. The section welcomes submissions which support and advance the SDG: SDG 9: Industry, Innovation and Infrastructure. The Networks and Communications section does not consider submissions that lack a clear focus on network technologies, communication protocols, or related computational aspects. Studies primarily centered on non-technical fields, such as sociology, psychology, or economics, without a strong connection to networks and communications, are outside the scope of this section. However, interdisciplinary research that integrates these fields with a strong emphasis on networks and communications, and contributes to the advancement of industry, innovation, and infrastructure, may be considered. This multidisciplinary section is at the forefront of disseminating and communicating cutting-edge scientific knowledge and impactful discoveries in the field of computer networking and communication to researchers, industry, policymakers, and the public worldwide. | D4: 1511 | E4: Frontiers in Computer Science | F4: =VLOOKUP(D4,分野ID!$A$2:$B$49,2,FALSE) -> Computer Science
A5: 524 | B5: Primary Immunodeficiencies | C5: The Primary Immunodeficiencies section is dedicated to publishing research focused on understanding and addressing primary immunodeficiencies in humans. Led by Dr. Fabio Candotti from Centre Hospitalier Universitaire Vaudois (CHUV), and Dr. Isabelle Meyts from KU Leuven, the Primary Immunodeficiencies section welcomes submissions in the various domains of immunodeficiency research, which aim to enhance communication and collaboration between clinicians and investigators for the advancement of human translational and basic research. Topics considered in the scope of this section include: Submissions should provide detailed, in-depth knowledge about the various aspects of primary immunodeficiencies, ultimately contributing to the development of more specific and sustained therapies. The section welcomes submissions which support and advance the SDG: SDG 3: Good Health and Well-being. The Primary Immunodeficiencies section does not consider submissions focused on general viral infections, hepatitis, or metabolic studies, as these topics fall outside the scope of primary immunodeficiencies and related research. However, the section does welcome submissions that provide detailed, in-depth knowledge about various aspects of primary immunodeficiencies, ultimately contributing to the development of more specific and sustained therapies, and supporting the advancement of good health and well-being. While the section excludes broader infectious disease research and unrelated analytical methods, it encourages submissions that employ appropriate methodologies for the study of primary immunodeficiencies. This multidisciplinary section is at the forefront of disseminating and communicating cutting-edge scientific knowledge and impactful discoveries in the field of immunodeficiency research to researchers, industry, policymakers, and the public worldwide. | D5: 276 | E5: Frontiers in Immunology | F5: =VLOOKUP(D5,分野ID!$A$2:$B$49,2,FALSE) -> Immunology
A6: 1635 | B6: Ophthalmology | C6: The Ophthalmology section of Frontiers in Medicine publishes research that advances the understanding, diagnosis and treatment ocular diseases. Led by Prof. Jodhbir Mehta from Singapore National Eye Center, the Ophthalmology specialty welcomes submissions across all clinical subspecialities, from traditional to newer disciplines such as myopia, trauma and primary care, to ultimately improve patient care and outcomes. Topics considered in-scope for this section include: Research published in the section supports and advances SDG 3: Good Health and Well-being. Studies on the anatomy, physiology, disorders or treatment of the afferent visual pathway, higher cortical visual systems, vascular tree as regards the retina and optic nerve, pupils, eye movements and pain are out of scope for the Ophthalmology section of Frontiers in Medicine , and should instead be submitted to the Neuro-Ophthalmology section of Frontiers in Neurology . This multidisciplinary section is at the forefront of disseminating and communicating cutting-edge scientific knowledge and impactful discoveries in the field of Ophthalmology to researchers, industry, policymakers, and the public worldwide. | D6: 602 | E6: Frontiers in Medicine | F6: =VLOOKUP(D6,分野ID!$A$2:$B$49,2,FALSE) -> Medicine
A7: 61 | B7: Quantitative Psychology and Measurement | C7: The Quantitative Psychology and Measurement section is dedicated to publishing research focused on advancing best practices in quantitative methods and measurement within social and behavioral sciences. Led by Dr. Pietro Cipresso from the University of Turin, the Quantitative Psychology and Measurement section welcomes submissions in various domains of quantitative psychology, which connect theory and practice to enhance research outcomes in the social sciences. Topics considered in the scope of this section include: Submissions should provide detailed, in-depth knowledge about the application of best practices in quantitative methods and measurement to answer important questions in substantive areas of social sciences. The section welcomes submissions which support and advance the SDGs: SDG 4: Quality Education, SDG 16: Peace, Justice and Strong Institutions, and SDG 17: Partnerships for the Goals. The Quantitative Psychology and Measurement section does not consider submissions focusing solely on healthcare management, marketing and consumer behavior, public policy and governance, human resources and job satisfaction, or education and training programs without a clear connection to quantitative psychological research and measurement methodologies. This multidisciplinary section is at the forefront of disseminating and communicating cutting-edge scientific knowledge and impactful discoveries in the field of quantitative psychology to researchers, industry, policymakers, and the public worldwide. | D7: 36 | E7: Frontiers in Psychology | F7: =VLOOKUP(D7,分野ID!$A$2:$B$49,2,FALSE) -> Psychology
A8: 682 | B8: Pediatric Pulmonology | C8: The Pediatric Pulmonology section is dedicated to publishing research focused on advancing the understanding and treatment of pediatric respiratory disorders. Led by Prof Dr. Anne Chang from the Queensland Children's Hospital and Menzies School of Health Research, the Pediatric Pulmonology section welcomes submissions in the various domains of pediatric pulmonology, which aim to enhance clinical outcomes and stimulate research, particularly in under-resourced settings. Topics considered in the scope of this section include: Submissions should provide detailed, in-depth knowledge about the various aspects of pediatric pulmonology, with a focus on translational applications and novel techniques that have the potential to improve patient outcomes. In particular, the section welcomes submissions which support and advance the understanding and treatment of pediatric respiratory disorders, pediatric pulmonology, and translational applications in under-resourced settings (SDG 3: Good Health and Well-being). The Pediatric Pulmonology section does not consider submissions that lack relevance to pediatric respiratory health. This includes studies that primarily address adult populations or non-respiratory pediatric conditions. However, research that has direct implications for the diagnosis, treatment, or management of pediatric pulmonary disorders, even if not exclusively focused on pediatric populations, may be considered if it contributes to the advancement of understanding and treatment in pediatric pulmonology and supports the improvement of patient outcomes in under-resourced settings. This multidisciplinary section is at the forefront of disseminating and communicating cutting-edge scientific knowledge and impactful discoveries in the field of pediatric pulmonology to researchers, industry, policymakers, and the public worldwide. | D8: 606 | E8: Frontiers in Pediatrics | F8: =VLOOKUP(D8,分野ID!$A$2:$B$49,2,FALSE) -> Pediatrics
A9: 956 | B9: Computer Security | C9: The Computer Security section is dedicated to publishing research focused on the protection and safety of computer systems and networks. Led by Dr. Nicola Zannone from Eindhoven University of Technology, the Computer Security section welcomes submissions in the various domains of computer and network security, which connect and integrate the principles and applications within related disciplines. Topics considered in the scope of this section include: Submissions should provide detailed, in-depth knowledge about the various aspects of computer and network security, aiming to advance the understanding and application of security measures in diverse contexts. The section welcomes submissions which support and advance the SDG: SDG 9: Industry, Innovation and Infrastructure. The Computer Security section does not consider submissions that are unrelated to the field of computer security. For example, those focusing on general computer science, hardware engineering, or software development without a relevance to security aspects will not be considered. However, studies that involve the application of security measures in diverse contexts, such as financial systems, healthcare and medical systems, transportation systems, and utilities and industry, are welcome. Additionally, submissions should have a strong technical or theoretical foundation in computer security to be considered for publication. This multidisciplinary section is at the forefront of disseminating and communicating cutting-edge scientific knowledge and impactful discoveries in the field of computer and network security to researchers, industry, policymakers, and the public worldwide. | D9: 1511 | E9: Frontiers in Computer Science | F9: =VLOOKUP(D9,分野ID!$A$2:$B$49,2,FALSE) -> Computer Science
A10: 2627 | B10: Complex Physical Systems | C10: This section of Frontiers devoted to Complex Physical Systems is dedicated to the exploration of the various forms of complexity displayed by physical systems at large. Led by Prof Sauro Succi, of the Italian Institute of Technology (IIT) and Harvard University, this section welcomes submission in all domains of the physical sciences which exhibit complex behaviour and show potential for novel interdisciplinary connections. Topics considered in the scope of this section include: Submissions should provide detailed, in-depth knowledge about the interplay of multiple physical mechanisms and their implications for complex systems in physics, chemistry, and biology. In particular, the section welcomes submissions which support and advance the active and biological systems, complexity at the interface between physics and biology, complexity in quantum systems, energy-saving materials, fluid motion at all scales, glassy systems, machine-learning assisted multiscale simulations, and soft flowing matter in SDGs 7 (Affordable and Clean Energy), 9 (Industry, Innovation and Infrastructure), and 13 (Climate Action). The Complex Physical Systems section does not consider submissions that lack a clear focus on the complexity and interdisciplinary nature of physical systems. Studies that primarily address isolated aspects or conventional approaches without exploring the intricate interactions and emergent properties of complex systems, such as active and biological systems, complexity at the interface between physics and biology, complexity in quantum systems, energy-saving materials, fluid motion at all scales, glassy systems, machine-learning assisted multiscale simulations, and soft flowing matter, are outside the scope of this section. The section is not devoted to the study of complex phenomena outside the realm of physics, unless dealing with techniques developed elsewhere that can be carried on to the physics domain. The section does not accepted submissions explicitly devoted to the subjects which belong to military research. This multidisciplinary section is at the forefront of disseminating and communicating cutting-edge scientific knowledge and impactful discoveries in the field of complex physical systems to researchers, industry, policymakers, and the public worldwide. | D10: 616 | E10: Frontiers in Physics | F10: =VLOOKUP(D10,分野ID!$A$2:$B$49,2,FALSE) -> Physics
A11: 1708 | B11: Environmental & Occupational Determinants | C11: The Environmental & Occupational Determinants section is dedicated to publishing research focused on the impact of environmental and occupational factors on allergic diseases. Led by Dr. Torben Sigsgaard from Aarhus University, the Environmental & Occupational Determinants section welcomes submissions in various domains of allergy research, which explore the connections between environmental and occupational exposures and their effects on health. Topics considered in the scope of this section include: Submissions should provide detailed, in-depth knowledge about the influence of environmental and occupational factors on the development and manifestation of allergic diseases. In particular, the section welcomes submissions which support and advance the environmental and occupational determinants of allergic diseases and their impact on health, in alignment with SDG 3 (Good Health and Well-being), SDG 11 (Sustainable Cities and Communities), and SDG 13 (Climate Action). The Environmental & Occupational Determinants section does not consider studies dealing with general environmental pollutants or broader correlations between the environment and health that do not specifically focus on aerobiology and allergies. Additionally, research on clinical treatments, individual behavior, or unrelated social issues that do not contribute to understanding the impact of environmental or occupational determinants on health outcomes is outside the scope of this section. This multidisciplinary section is at the forefront of disseminating and communicating cutting-edge scientific knowledge and impactful discoveries in the field of allergy research to researchers, industry, policymakers, and the public worldwide. | D11: 1705 | E11: Frontiers in Allergy | F11: =VLOOKUP(D11,分野ID!$A$2:$B$49,2,FALSE) -> #N/A
A12: 834 | B12: Food Chemistry | C12: The Food Chemistry section is dedicated to publishing research focused on the structural and functional characterization of food components. Led by Dr. Michael Rychlik from Technical University of Munich, the Food Chemistry section welcomes submissions in various domains of food chemistry, which connect the understanding of molecular food technology to bioactivity in a broad sense. Topics considered in the scope of this section include: Submissions should provide detailed, in-depth knowledge about the structural, functional, and bioactive properties of food components and their interactions with various factors. Bioactivities reported may include sensory, nutritional, physiological, or toxicological properties. In particular, the section welcomes submissions which support and advance the Food Chemistry research and Sustainable Development Goals (SDGs) such as Zero Hunger (SDG 2), Good Health and Well-being (SDG 3), and Responsible Consumption and Production (SDG 12). The Food Chemistry section does not consider submissions focusing solely on animal studies, pharmaceuticals, or medical treatments, as these topics fall outside the scope of food chemistry and its related research areas. This multidisciplinary section is at the forefront of disseminating and communicating cutting-edge scientific knowledge and impactful discoveries in the field of food chemistry to researchers, industry, policymakers, and the public worldwide. | D12: 628 | E12: Frontiers in Nutrition | F12: =VLOOKUP(D12,分野ID!$A$2:$B$49,2,FALSE) -> Nutrition
A13: 1593 | B13: Cognitive Neuroscience | C13: The Cognitive Neuroscience section is dedicated to publishing research focused on understanding the neural basis of human cognition and behavior. Led by Dr. Lutz Jäncke from the University of Zurich, the Cognitive Neuroscience section welcomes submissions in various domains of cognitive neuroscience, which aim to integrate and cross-link research in the field. Topics considered in the scope of this section include: Submissions should provide detailed, in-depth knowledge about the neural underpinnings of human cognition and behavior. The section welcomes submissions which support and advance the SDG: SDG 3 - Good Health and Well-being and SDG 4 - Quality Education. The Cognitive Neuroscience section does not consider submissions focusing solely on medical treatment, physical therapy, nursing, or preoperative care, as these fields are beyond the scope of cognitive neuroscience research. However, studies that integrate these fields with the neural basis of cognition or human cognition-related behaviors (such as memory, attention, executive functions, perception, reasoning, decision making, emotion, motivation, movement, language, learning, hemispheric asymmetry and brain plasticity etc), particularly in the context of promoting good health and well-being or quality education, are welcome. Studies that do not primarily investigate the neural basis of cognition or cognition-related behaviors will not be considered for this section. This multidisciplinary section is at the forefront of disseminating and communicating cutting-edge scientific knowledge and impactful discoveries in the field of cognitive neuroscience to researchers, industry, policymakers, and the public worldwide. | D13: 1588 | E13: Frontiers in Human Neuroscience | F13: =VLOOKUP(D13,分野ID!$A$2:$B$49,2,FALSE) -> Human Neuroscience
... A100: 76 | B100: Mood Disorders | C100: The Mood Disorders section is dedicated to publishing research from various scientific and clinical disciplines that investigates causes and treatments of mood disorders, whether as a primary diagnosis or co-morbid with other disorders. Led by Prof. Paul Stokes from King's College London, the Mood Disorders section aims to improve lives of people with Mood Disorders by rapidly communicating and publicizing key discoveries, fostering collaborative multidisciplinary research, and providing a forum where ideas can be exchanged and debated. Topics considered in the scope of this section include, but are not limited to: Submissions should provide detailed, in-depth knowledge about the various aspects of mood disorders and/or facilitate collaboration between researchers and clinicians working in this field. The Mood Disorders section does not consider bibliographic reviews. Case Reports are required to significantly advance the field, must be completely anonymised, and should be discussed in advance of submission with the Section Chief Editor. This multidisciplinary section is at the forefront of disseminating and communicating cutting-edge scientific knowledge and impactful discoveries in the field of psychiatry to researchers, industry, policymakers, and the public worldwide. | D100: 71 | E100: Frontiers in Psychiatry | F100: =VLOOKUP(D100,分野ID!$A$2:$B$49,2,FALSE) -> Psychiatry
A101: 1077 | B101: Earth Sciences | D101: 979 | E101: Frontiers for Young Minds | F101: =VLOOKUP(D101,分野ID!$A$2:$B$49,2,FALSE) -> #N/A
A102: 2107 | B102: Thermal Science and Energy Systems | C102: The Thermal Science and Energy Systems section is dedicated to publishing research focused on experimental and simulation studies having new ideas and preliminary findings in the field of heat and mass transfer and/or fluid flow, and technologies in the thermal engineering field. Led by Dr. Omid Mahian from Ningbo University, the Thermal Science and Energy Systems section welcomes submissions in the various domains of thermal engineering, which connect interdisciplinary research to address global challenges such as climate change, sustainable development, and the UN sustainable development goals (SDGs). Special attention is paid to the latest technological breakthroughs and material innovation in the field of thermal science supporting interdisciplinary research. Topics considered in the scope of this section include: Submissions should provide detailed, in-depth knowledge about the development, analysis, and optimization of thermal systems and energy technologies. This multidisciplinary section is at the forefront of disseminating and communicating cutting-edge scientific knowledge and impactful discoveries in the field of thermal engineering to researchers, industry, policymakers, and the public worldwide. | D102: 2105 | E102: Frontiers in Thermal Engineering | F102: =VLOOKUP(D102,分野ID!$A$2:$B$49,2,FALSE) -> #N/A
A103: 2065 | B103: Cost and Resource Allocation | C103: The Cost and Resource Allocation section is dedicated to publishing research focused on innovative methodologies and applications in health economics and financing. Led by Prof Jose M Valderas from the National University of Singapore, the Cost and Resource Allocation section welcomes submissions in various domains of health economics and healthcare financing, which address challenges and solutions related to the efficient and equitable allocation of healthcare resources. This section emphasizes diverse research perspectives, including cross-cultural and non-Western contexts, as well as environmental factors that influence healthcare resource allocation. Topics considered in the scope of this section include: Submissions should provide detailed, in-depth knowledge about the efficient and equitable allocation of healthcare resources, as well as methodological challenges and solutions in health economics. In particular, the section welcomes submissions which support and advance the efficient and equitable allocation of healthcare resources, methodological challenges and solutions in health economics, and cross-cultural perspectives in relation to SDG 3 (Good Health and Well-being) and SDG 10 (Reduced Inequalities). The Cost and Resource Allocation section does not consider submissions focusing solely on clinical treatment outcomes without a fundamental basis in resource allocation strategies, healthcare economics, or policy implications. Studies that do not address the broader context of resource management in healthcare, including access to care, innovative approaches to generating evidence, financing healthcare, and disparities across different racial and ethnic groups, will be considered out of scope for this section. This multidisciplinary section is at the forefront of disseminating and communicating cutting-edge scientific knowledge and impactful discoveries in the field of health economics to researchers, industry, policymakers, and the public worldwide. | D103: 2063 | E103: Frontiers in Health Services | F103: =VLOOKUP(D103,分野ID!$A$2:$B$49,2,FALSE) -> #N/A
A104: 155 | B104: Neuro-Otology | C104: The Neuro-Otology section is dedicated to publishing research focused on advancing the understanding of neuro-otological and oto-neurological disorders and their underlying pathomechanisms and etiology, including genetics. Led by Dr. Michael Strupp from Ludwig Maximilian University of Munich, the Neuro-Otology section welcomes submissions in various domains of neuro-otology and oto-neurology. They aim to enhance the interdisciplinary collaboration of clinical and basic vestibular and audiological research, namely between ENT, neurology and audiology as well as between neurophysiology, neuroanatomy, and genetics. Topics considered in the scope of this section include: Submissions can, for instance, provide detailed, in-depth knowledge about the function and dysfunctions of the peripheral or central vestibular or audiological systems, as well as their implications for the diagnosis and treatment of vertigo, dizziness, imbalance, gait disorders, and hearing problems. The section welcomes submissions which support and advance the SDG: SDG 3: Good Health and Well-being. The Neuro-Otology section does not consider submissions focused on fields outside the scope of neuro-otological/oto-neurological studies. However, we recognize that some interdisciplinary research may indirectly contribute to the understanding of the auditory and vestibular systems. Therefore, we will evaluate submissions related to electron microscopy, materials science, or artificial neural networks on a case-by-case basis, considering their relevance and potential impact on neuro-otological research and the advancement of good health and well-being. The Neuro-Otology section does not accept Case Reports. This multidisciplinary section is at the forefront of disseminating and communicating cutting-edge scientific knowledge and impactful discoveries in the field of neuro-otology to researchers, clinicians, as well as industry, policymakers, and the public worldwide. | D104: 141 | E104: Frontiers in Neurology | F104: =VLOOKUP(D104,分野ID!$A$2:$B$49,2,FALSE) -> Neurology
A105: 3487 | B105: Bioengineering | C105: The Bioengineering section is dedicated to publishing research focused on advancing transplantation medicine through innovative bioengineering approaches. Led by Dr. Wei Tao from Harvard Medical School, the Bioengineering section welcomes submissions in the various domains of transplantation bioengineering, which connect interdisciplinary fields to address critical needs in transplantation medicine. Topics considered in the scope of this section include: Submissions should provide detailed, in-depth knowledge about innovative and effective approaches in transplantation bioengineering. In particular, the section welcomes submissions which support and advance the transplantation bioengineering, biomedical device, biomaterials, biomechanics, cellular engineering, diagnostic and bioimaging, immunoengineering, nanobiotechnology, organ engineering, regenerative medicine, and tissue engineering in relation to SDG 3 (Good Health and Well-being) and SDG 9 (Industry, Innovation, and Infrastructure). This multidisciplinary section is at the forefront of disseminating and communicating cutting-edge scientific knowledge and impactful discoveries in the field of transplantation bioengineering to researchers, industry, policymakers, and the public worldwide. | D105: 2417 | E105: Frontiers in Transplantation | F105: =VLOOKUP(D105,分野ID!$A$2:$B$49,2,FALSE) -> #N/A
A106: 2209 | B106: Molecular Mechanisms of Immune Response | C106: The Molecular Mechanisms of Immune Response section is dedicated to publishing research focused on understanding the molecular basis of immune responses in various physiological and pathological contexts. Led by Dr. Stefania Grimaudo from the University of Palermo, the Molecular Mechanisms of Immune Response section welcomes submissions in the various domains of molecular medicine, which aim to enhance the knowledge and understanding of immune response pathways and their implications in disease prevention and treatment. Topics considered in the scope of this section include: Submissions should provide detailed, in-depth knowledge about the molecular mechanisms and pathways involved in immune responses and their implications in various diseases and disorders. In particular, the section welcomes submissions which support and advance the understanding of molecular mechanisms of immune response, inflammation-mediated tissue injury, chronic disease pathogenesis, immune system disorders, and dysregulation of inflammation pathways in relation to SDG 3 (Good Health and Well-being). This multidisciplinary section is at the forefront of disseminating and communicating cutting-edge scientific knowledge and impactful discoveries in the field of molecular medicine to researchers, industry, policymakers, and the public worldwide. | D106: 2086 | E106: Frontiers in Molecular Medicine | F106: =VLOOKUP(D106,分野ID!$A$2:$B$49,2,FALSE) -> #N/A
A107: 1326 | B107: Biodiversity | D107: 979 | E107: Frontiers for Young Minds | F107: =VLOOKUP(D107,分野ID!$A$2:$B$49,2,FALSE) -> #N/A
A108: 1379 | B108: Forests and the Atmosphere | C108: The Forests and the Atmosphere section is dedicated to publishing research focused on the interactions between forests and the atmosphere across various scales under changing climate conditions. Led by Dr. Jaana Bäck from the University of Helsinki and Dr. Jörg-Peter Schnitzler from the Helmholtz Center München, Helmholtz Association of German Research Centres (HZ), the Forests and the Atmosphere section welcomes submissions in the various domains of forest and atmospheric research, which aim to enhance understanding of biosphere-atmosphere interactions and their impact on Earth's climate sensitivity. Topics considered in the scope of this section include: Submissions should provide detailed, in-depth knowledge about the complex mechanisms underlying forest-atmosphere interactions, employing state-of-the-art technology and approaches in plant and tree physiology, biogeochemistry, and process-based modeling. Interdisciplinary approaches are particularly encouraged. In particular, the section welcomes submissions which support and advance the understanding of forest-atmosphere interactions in alignment with SDGs 13 (Climate Action), 15 (Life on Land), and 17 (Partnerships for the Goals). This multidisciplinary section is at the forefront of disseminating and communicating cutting-edge scientific knowledge and impactful discoveries in the field of forest and atmospheric research to researchers, industry, policymakers, and the public worldwide. | D108: 1366 | E108: Frontiers in Forests and Global Change | F108: =VLOOKUP(D108,分野ID!$A$2:$B$49,2,FALSE) -> Forests and Global Change
A109: 2256 | B109: Construction Materials | C109: The Construction Materials section is dedicated to publishing research focused on the development and application of construction materials in infrastructure and buildings. Led by Dr. Bjorn Birgisson from the University of Georgia, the Construction Materials section welcomes submissions in the various domains of construction materials, which connect the development, processing, evaluation, applications, and performance of these materials in civil engineering. Topics considered in the scope of this section include: Submissions should provide detailed, in-depth knowledge about the development and application of construction materials in infrastructure and buildings. In particular, the section welcomes submissions which support and advance the development and application of construction materials in infrastructure and buildings, contributing to SDG 9 (Industry, Innovation, and Infrastructure) and SDG 11 (Sustainable Cities and Communities). The Construction Materials section does not consider studies centered on pure materials research, materials life cycle analysis, or non-material aspects such as project management, architectural design, or unrelated engineering disciplines. However, submissions that focus on the development, processing, evaluation, applications, and performance of construction materials in infrastructure and buildings, while also contributing to sustainable development and urban planning, are welcomed. This multidisciplinary section is at the forefront of disseminating and communicating cutting-edge scientific knowledge and impactful discoveries in the field of construction materials to researchers, industry, policymakers, and the public worldwide. | D109: 921 | E109: Frontiers in Built Environment | F109: =VLOOKUP(D109,分野ID!$A$2:$B$49,2,FALSE) -> #N/A
A110: 2334 | B110: Therapy in Gastroenterology | C110: The Therapy in Gastroenterology section is dedicated to publishing research focused on innovative treatments in gastroenterology and hepatology. Led by a team of expert researchers and clinicians, the Therapy in Gastroenterology section welcomes submissions in various domains of gastroenterology and hepatology, which aim to advance the understanding and development of novel therapeutic approaches. Topics considered in the scope of this section include: Submissions should provide detailed, in-depth knowledge about innovative treatments and interventions in gastroenterology and hepatology, with a focus on recently developed substances, endoscopic or surgical treatments, and lifestyle modifications. The section welcomes submissions which support and advance the SDG 3: Good Health and Well-being. The Therapy in Gastroenterology section does not consider submissions focusing on hospital administration, safety regulations, or general disease prevention strategies that do not directly pertain to gastroenterological conditions or therapeutic interventions. Studies without a relevance to gastroenterology or its therapeutic approaches are outside the scope of this section. This multidisciplinary section is at the forefront of disseminating and communicating cutting-edge scientific knowledge and impactful discoveries in the field of gastroenterology and hepatology to researchers, industry, policymakers, and the public worldwide. | D110: 2333 | E110: Frontiers in Gastroenterology | F110: =VLOOKUP(D110,分野ID!$A$2:$B$49,2,FALSE) -> #N/A
A111: 1623 | B111: Developmental and Reproductive Toxicology | C111: The Developmental and Reproductive Toxicology section is dedicated to publishing research focused on understanding the impact of environmental chemicals on human and animal development and reproductive health. Led by Prof. Terje Svingen from the National Food Institute, Technical University of Denmark, the Developmental and Reproductive Toxicology section welcomes submissions in various domains of toxicology, which aim to enhance our understanding of the effects of harmful chemicals on early-life development and reproductive processes. Topics considered within the scope of this section include: Submissions should provide detailed, in-depth knowledge about the effects of chemical substances on developmental and reproductive processes, with a focus on understanding the underlying mechanisms and pathways. In particular, the section welcomes submissions which support and advance the understanding of the impact of environmental chemicals on human and animal development and reproductive health, and the development of alternative testing methods (SDGs 3, 6, 12, and 15). The Developmental and Reproductive Toxicology section does not consider submissions focused on plant biology. However, studies that rely on animal testing may be considered if they have a fundamental basis in toxicology and contribute to our understanding of the impact of environmental chemicals on human and animal development and reproductive health. Studies that do not address the impact of toxicants on human development or reproduction are outside the scope of this section. This multidisciplinary section is at the forefront of disseminating and communicating cutting-edge scientific knowledge and impactful discoveries in the field of toxicology to researchers, industry, policymakers, and the public worldwide. | D111: 473 | E111: Frontiers in Toxicology | F111: =VLOOKUP(D111,分野ID!$A$2:$B$49,2,FALSE) -> #N/A
A112: 532 | B112: Alloimmunity and Transplantation | C112: The Alloimmunity and Transplantation section is dedicated to publishing research focused on advancing the understanding and management of alloimmune responses and transplantation outcomes in a precision medicine approach. Led by Dr. Antoine Toubert from Université Paris Cité, and Dr. Effie Petersdorf from Fred Hutchinson Cancer Research Center, the Alloimmunity and Transplantation section welcomes submissions in the various domains of alloimmunity and transplantation, which aim to enhance the connection between basic sciences and clinical research. Topics considered in the scope of this section include: Submissions should provide detailed, in-depth knowledge about the various aspects of alloimmunity and transplantation, aiming to improve patient outcomes and quality of life. Immunological aspects of autologous hematopoietic stem cell transplantation are also covered. In particular, the section welcomes submissions which support and advance the understanding and management of alloimmune responses and transplantation outcomes, major histocompatibility complex and immunogenetics, tolerance in an allogeneic setting, immune reconstitution after allogeneic and autologous hematopoietic stem cell transplantation, innovative immunosuppressive strategies and biotherapies, cellular therapy in the control of allogeneicity (including CAR T cells), novel donor sources and availability in organ transplantation and hematopoietic stem cell transplantation, ethics of organ and hematopoietic stem cell transplantation donation, and impact on quality of life, in line with SDG 3 (Good Health and Well-being). The Alloimmunity and Transplantation section does not consider submissions focused on DNA methylation, gene expression, tumor research, sepsis, or platelet function, as these topics fall outside the scope of alloimmunity and transplantation research. This multidisciplinary section is at the forefront of disseminating and communicating cutting-edge scientific knowledge and impactful discoveries in the field of alloimmunity and transplantation to researchers, industry, policymakers, and the public worldwide. | D112: 276 | E112: Frontiers in Immunology | F112: =VLOOKUP(D112,分野ID!$A$2:$B$49,2,FALSE) -> Immunology
A113: 822 | B113: Urban Ecology | C113: The Urban Ecology section is dedicated to publishing research focused on understanding the complex biological components and processes of urban areas. Led by Dr. Juan Diego Ibáñez-Álamo from the University of Granada, the Urban Ecology section welcomes submissions in various domains of urban ecology which connect interdisciplinary approaches to comprehend urban ecosystems. Topics considered in the scope of this section include: Submissions should provide detailed, in-depth knowledge about interactions and processes within urban ecosystems. The term “urban” can be used broadly to refer to human settlements and their transitions over a range of scales and definitions, from local political and land use/land cover–based definitions to larger geographic boundaries. We are also happy to consider studies on the translation of findings in urban ecology into practice through development and testing of solutions to urban environmental and social problems, and through innovative approaches to planning, building, and managing cities, as long as they still show a clear link to ecology. The Urban Ecology section does not consider submissions focusing purely on human health and well-being, urban planning, or socio-economic studies. Authors should mention, in the methods or acknowledgements, any Field Stations or Marine Laboratories (FSMLs) where the research was conducted or that supported the research (e.g., assisted with permitting, facilitated land or data access, provided housing accommodations or research space, granted funding, etc.). This also includes others places of scientific infrastructure (e.g., botanical gardens, national laboratories, museums). Please include the FSML’s Research Organization Registry (ROR) number if available. This multidisciplinary section is at the forefront of disseminating and communicating cutting-edge scientific knowledge and impactful discoveries in the field of urban ecology to researchers, industry, policymakers, and the public worldwide. | D113: 471 | E113: Frontiers in Ecology and Evolution | F113: =VLOOKUP(D113,分野ID!$A$2:$B$49,2,FALSE) -> Ecology and Evolution
A114: 1585 | B114: Modeling and Optimization for Decision Support | C114: The Modeling and Optimization for Decision Support section is dedicated to publishing research focused on advancing multi-criteria decision-making methods for sustainable development. Led by Dr. Jingzheng Ren from Hong Kong Polytechnic University, the Modeling and Optimization for Decision Support section welcomes submissions in various domains of multi-criteria decision-making, which facilitate sustainable-production-oriented decision-making, design, and optimization leading to a more sustainable society. Topics considered in the scope of this section include: Submissions should provide detailed, in-depth knowledge about multi-criteria decision-making for promoting cleaner production and sustainable development, with a focus on interdisciplinary subjects such as engineering, management science, and social science. In particular, the section welcomes submissions which support and advance the focus areas of Modeling and Optimization for Decision Support in promoting cleaner production, sustainable development, and interdisciplinary studies, aligning with SDGs 9 (Industry, Innovation, and Infrastructure), 12 (Responsible Consumption and Production), and 17 (Partnerships for the Goals). This multidisciplinary section is at the forefront of disseminating and communicating cutting-edge scientific knowledge and impactful discoveries in the field of multi-criteria decision-making to researchers, industry, policymakers, and the public worldwide. | D114: 1547 | E114: Frontiers in Sustainability | F114: =VLOOKUP(D114,分野ID!$A$2:$B$49,2,FALSE) -> #N/A
A115: 694 | B115: Quaternary Science, Geomorphology and Paleoenvironment | C115: The Quaternary Science, Geomorphology and Paleoenvironment section is dedicated to publishing research focused on Earth systems in the past 2.6 million years. Led by Dr. Steven Forman from Baylor University, the Quaternary Science, Geomorphology and Paleoenvironment section welcomes submissions aimed at understanding, modelling, and quantifying the spatial and temporal variations of Earth surface processes, and evaluating past environmental and climate changes of Earth systems, particularly associated with human evolution and environmental interactions from associated geomorphic, sedimentary, ice and biogenic and non-biogenic carbonate archives, particularly in reference to recent human-induced global climate change. Topics considered in the scope of this section include: In particular, the section welcomes submissions supporting and advancing SDG 13 (Climate Action), SDG 14 (Life Below Water), and SDG 15 (Life on Land). This multidisciplinary section is at the forefront of disseminating and communicating cutting-edge scientific knowledge and impactful discoveries in the field of Earth system science to researchers, industry, policymakers, and the public worldwide. | D115: 654 | E115: Frontiers in Earth Science | F115: =VLOOKUP(D115,分野ID!$A$2:$B$49,2,FALSE) -> Earth Science
A116: 1572 | B116: Quantitative Sustainability Assessment | C116: The Quantitative Sustainability Assessment section is dedicated to publishing research focused on understanding the environmental, social, and economic implications of various technologies, processes, materials, and policies for a sustainable future. Led by Dr. Maria Molinos-Senante from the Pontificia Universidad Catolica de Chile and Dr. Shabbir Gheewala from the King Mongkut's University of Technology Thonburi, the Quantitative Sustainability Assessment section welcomes submissions in the various domains of sustainability assessment, which address the challenges and complexities of the field. Topics considered in the scope of this section include: Submissions should provide detailed, in-depth knowledge about the methodology, data, or implementation aspects of quantitative sustainability assessment, addressing challenges and advancing the field through a multidisciplinary approach. In particular, the section welcomes submissions which support and advance the focus areas of the Quantitative Sustainability Assessment section and SDGs, such as responsible consumption and production (SDG 12), climate action (SDG 13), clean water and sanitation (SDG 6), affordable and clean energy (SDG 7), industry, innovation, and infrastructure (SDG 9), and sustainable cities and communities (SDG 11). This multidisciplinary section is at the forefront of disseminating and communicating cutting-edge scientific knowledge and impactful discoveries in the field of sustainability assessment to researchers, industry, policymakers, and the public worldwide. | D116: 1547 | E116: Frontiers in Sustainability | F116: =VLOOKUP(D116,分野ID!$A$2:$B$49,2,FALSE) -> #N/A
A117: 701 | B117: Molecular Diagnostics and Therapeutics | C117: The Molecular Diagnostics and Therapeutics section is dedicated to publishing research focused on the development and application of diagnostic and therapeutic tools for clinical use. Led by Prof. Matteo Becatti from the Department of Experimental and Clinical Biomedical Sciences 'Mario Serio' at the University of Firenze, the Molecular Diagnostics and Therapeutics section welcomes submissions in various domains of molecular biosciences, which connect the identification of molecular targets and biomarkers to their clinical applications. Topics considered in the scope of this section include: Submissions should provide detailed, in-depth knowledge about the molecular diagnostics and therapeutics field, focusing on the topics listed above. In particular, the section welcomes submissions which support and advance the molecular diagnostics and therapeutics, focusing on drug and diagnostic co-developments, clinical trials, personalized medicine, disease detection and monitoring, emerging molecular technologies (including the design and development of medical devices, diagnostic tools, and drug delivery systems), genetic variations, novel molecular therapies, and regulatory and ethical issues, contributing to SDGs 3 (Good Health and Well-being) and 9 (Industry, Innovation, and Infrastructure). The Molecular Diagnostics and Therapeutics section does not consider submissions related to clinical trials, medical imaging, inflammation and immune response, mental health, unless they have a strong molecular diagnostics or therapeutics component. However, the section does focus on bioinformatic studies (including artificial intelligence techniques, such as machine learning and deep learning, to analyze complex molecular data, predict disease outcomes, and optimize diagnostic and therapeutic strategies.) identifying diagnostic or prognostic markers for diseases, with in silico data supported by validating results. Studies without relevance to diagnostics or therapeutics are outside the scope of this section. This multidisciplinary section is at the forefront of disseminating and communicating cutting-edge scientific knowledge and impactful discoveries in the field of molecular biosciences to researchers, industry, policymakers, and the public worldwide. | D117: 698 | E117: Frontiers in Molecular Biosciences | F117: =VLOOKUP(D117,分野ID!$A$2:$B$49,2,FALSE) -> Molecular Biosciences
A118: 2870 | B118: ADHD | C118: The ADHD section is dedicated to publishing research focused on advancing the understanding and treatment of ADHD and related neurodevelopmental disorders. Led by Dr. Cesar Soutullo MD PhD from the University of Texas Health Science Center at Houston, the ADHD section welcomes submissions in the various domains of ADHD research, which connect fundamental findings to clinical applications and promote a comprehensive understanding of the disorder. Topics considered in the scope of this section include: Submissions should provide detailed, in-depth knowledge about the various aspects of ADHD and its management, contributing to a better understanding of the disorder and improved patient outcomes. The section welcomes submissions which support and advance the SDG: SDG 3: Good Health and Well-being. The ADHD section does not consider submissions that primarily focus on general medicine without a relevance to ADHD. Studies that do not specifically address the diagnosis, treatment, or understanding of ADHD and its related conditions are outside the scope of this section. However, submissions related to genetics are welcome as long as they have a direct relevance to ADHD, its etiology, or its management. This multidisciplinary section is at the forefront of disseminating and communicating cutting-edge scientific knowledge and impactful discoveries in the field of ADHD research to researchers, industry, policymakers, and the public worldwide. | D118: 71 | E118: Frontiers in Psychiatry | F118: =VLOOKUP(D118,分野ID!$A$2:$B$49,2,FALSE) -> Psychiatry
A119: 3048 | B119: Energy Storage | C119: The Energy Storage section is committed to publishing research centered on advancing energy storage technologies for a sustainable future. Led by Dr. Kui Jiao from Tianjin University, the Energy Storage section encourages submissions in various domains of energy storage, which aim to facilitate the transition towards carbon neutrality and large-scale renewable energy utilization. Topics of interest to the Energy Storage section especially focus on the development of battery and thermal storage materials, renewable fuels for energy storage and utilization, life cycle assessment of energy storage technologies in complex scenarios, and integration system of energy storage and fluctuant renewable sources. Topics considered within the scope of this section include: Submissions should provide comprehensive, in-depth knowledge about the development, implementation, and assessment of energy storage technologies and materials. In particular, the section welcomes submissions which support and advance the focus areas of the Section and SDGs, such as affordable and clean energy (SDG 7), industry, innovation, and infrastructure (SDG 9), and climate action (SDG 13). This multidisciplinary section is at the forefront of disseminating and communicating cutting-edge scientific knowledge and impactful discoveries in the field of Energy Storage to researchers, industry, policymakers, and the public worldwide. | D119: 626 | E119: Frontiers in Energy Research | F119: =VLOOKUP(D119,分野ID!$A$2:$B$49,2,FALSE) -> Energy Research
... A184: 2609 | B184: Cardiometabolic Health | C184: The Cardiometabolic Health section is dedicated to publishing research focused on the intricate relationship between oral and cardiometabolic health. Led by Dr. Shilpa Bhupathiraju from Harvard Medical School, the Cardiometabolic Health section welcomes submissions in various domains of oral and cardiometabolic health research, which aim to enhance the understanding of the interplay between these two areas. Topics considered in the scope of this section include: Submissions should provide detailed, in-depth knowledge about the complex connections between oral and cardiometabolic health, as well as potential interventions and preventive measures. In particular the section welcomes submissions which contribute towards SDG 3 (Good Health and Well-being). Submissions which do not relate to the various domains of oral and cardiometabolic health research may be better suited to different sections within Frontiers in Oral Health, or other Frontiers journals, such as Frontiers in Dental Medicine. This multidisciplinary section is at the forefront of disseminating and communicating cutting-edge scientific knowledge and impactful discoveries in the field of oral and cardiometabolic health research to researchers, industry, policymakers, and the public worldwide. | D184: 1702 | E184: Frontiers in Oral Health | F184: =VLOOKUP(D184,分野ID!$A$2:$B$49,2,FALSE) -> Oral Health
A185: 978 | B185: Neuroscience and Psychology | D185: 979 | E185: Frontiers for Young Minds | F185: =VLOOKUP(D185,分野ID!$A$2:$B$49,2,FALSE) -> #N/A
A186: 1726 | B186: Psycho-Oncology | C186: The Psycho-Oncology section is dedicated to publishing research focused on the multidisciplinary aspects of cancer care, addressing psychological, behavioral, social, physical, and functional dimensions. Led by Dr. Anja Mehnert from University Hospital Leipzig, the Psycho-Oncology section welcomes submissions in various domains of psycho-oncology, which connect diverse aspects of cancer care, from prevention to end-of-life support. Topics considered in the scope of this section include: Submissions should provide detailed, in-depth knowledge about the various aspects of psycho-oncology, addressing the diverse challenges faced by cancer patients, their families, and healthcare providers. In particular, the section welcomes submissions which support and advance the multidisciplinary aspects of cancer care, psychological interventions, and psychotherapy in cancer care, addressing the diverse challenges faced by cancer patients, their families, and healthcare providers, and contributing to the achievement of SDGs 3 (Good Health and Well-being) and 17 (Partnerships for the Goals). The Psycho-Oncology section does not consider submissions focusing on cell biology, childhood development, or interpersonal relationships, unless they have a relevance to the psychological aspects of cancer care, prevention, or survivorship. Studies without a relevance to the psycho-oncological context are outside the scope of this section. This multidisciplinary section is at the forefront of disseminating and communicating cutting-edge scientific knowledge and impactful discoveries in the field of psycho-oncology to researchers, industry, policymakers, and the public worldwide. | D186: 36 | E186: Frontiers in Psychology | F186: =VLOOKUP(D186,分野ID!$A$2:$B$49,2,FALSE) -> Psychology
A187: 2415 | B187: Gastrointestinal Cancers: Gastric and Esophageal Cancers | C187: The Gastrointestinal Cancers: Gastric and Esophageal Cancers section is dedicated to publishing research focused on advancing the understanding and treatment of gastric and esophageal neoplasia. Led by Dr. Liang Qiao from the Faculty of Medicine and Health at The University of Sydney, the Gastrointestinal Cancers: Gastric and Esophageal Cancers section welcomes submissions in various domains of gastrointestinal cancer research, which aim to accelerate the clinical applications of biological advances. Topics considered in the scope of this section include: Submissions should provide detailed, in-depth knowledge about the mechanisms, prevention, early detection, and treatment of gastric and esophageal neoplasia. The section welcomes submissions which support and advance the SDG: SDG 3: Good Health and Well-being. The Gastrointestinal Cancers: Gastric and Esophageal Cancers section does not consider manuscripts focusing on cancer risk factors and stratification, as these topics may not directly contribute to the understanding and treatment of gastric and esophageal neoplasia. However, the section welcomes meta-analyses and descriptive studies based on rigorous statistical methods or systematic reviews. Additionally, studies containing purely surgical procedures treating Gastric and Esophageal Cancers are excluded, unless they are directly related to the integrated treatments of advanced cancer or endoscopic identification and treatment of early neoplasia. Case reports that are not well-studied (e.g., without correlative data, diagnosis not convincingly established, no research components, etc). While studies consisting solely of bioinformatics, computational analysis, or predictions without validation are not suitable, the section does consider research on molecular, genetic, and morphological biomarkers of tumor progression. Research on cost-effectiveness, preoperative training, molecular biology unrelated to cancer, real-time systems, or surgical complications without a fundamental basis in gastric or esophageal cancer research and treatment are not covered by this section. This multidisciplinary section is at the forefront of disseminating and communicating cutting-edge scientific knowledge and impactful discoveries in the field of gastrointestinal cancer research to researchers, industry, policymakers, and the public worldwide. | D187: 451 | E187: Frontiers in Oncology | F187: =VLOOKUP(D187,分野ID!$A$2:$B$49,2,FALSE) -> Oncology
