Workbook

Sheet まとめ

Sheet 類似度高分野ペア_要注意単語
B1: 心理学 vs 教育 | C1: 心理学 vs 人間の神経科学 | D1: 心理学 vs 精神医学 | E1: 心理学 vs 公衆衛生 | F1: 心臓血管医学 vs 内分泌学 | G1: 心臓血管医学 vs 医学 | H1: 政治学 vs 社会学 | I1: コミュニケーション vs 社会学 | J1: バイオエンジニアリングとバイオテクノロジー vs 細胞と発生生物学 | K1: 地球科学 vs 海洋科学 | L1: 免疫学 vs 腫瘍学
A2: 1 | B2: method | C2: regulation | D2: cognitive | E2: functional | F2: imaging | G2: intervention | H2: work | I2: design | J2: processing | K2: method | L2: function | N2: 高類似度＝cos平均値が0.25以上
A3: 2 | B3: methods | C3: cognitive | D3: flow | E3: cognitive | F3: development | G3: learning | H3: findings | I3: model | J3: flow | K3: standard | L3: functions
A4: 3 | B4: learning | C4: stimulation | D4: formation | E4: performance | F4: flow | G4: analyses | H4: study | I4: case | J4: inhibition | K4: measures | L4: intervention
A5: 4 | B5: regulation | C5: performance | D5: effect | E5: condition | F5: understanding | G5: structure | H5: related | I5: work | J5: system | K5: interaction | L5: figures
A6: 5 | B6: cognitive | C6: functional | D6: interaction | E6: formation | F6: exposure | G6: methods | H6: process | I6: attention | J6: factors | K6: interactions | L6: imaging
A7: 6 | B7: effect | C7: flow | D7: image | E7: development | F7: formation | G7: analysis | H7: development | I7: related | J7: methods | K7: imaging | L7: generated
A8: 7 | B8: effects | C8: attention | D8: effects | E8: target | F8: intervention | G8: signaling | H8: case | I8: processing | J8: analysis | K8: processing | L8: exposure
A9: 8 | B9: exposure | C9: related | D9: standard | E9: exposure | F9: features | G9: method | H9: attention | I9: based | J9: derived | K9: functions | L9: design
A10: 9 | B10: standard | C10: understanding | D10: signaling | E10: assessment | F10: regulation | G10: stimulation | H10: design | I10: subjects | J10: imaging | K10: methods | L10: formation
A11: 10 | B11: contributions | C11: formation | D11: form | E11: function | F11: structure | G11: formation | H11: affected | I11: performance | J11: design | K11: signaling | L11: learning
A12: 11 | B12: process | C12: processing | D12: context | E12: contributions | F12: learning | G12: development | H12: determined | I12: resulting | J12: patterns | K12: sequences | L12: functional
A13: 12 | B13: assessment | C13: evidence | D13: inhibition | E13: learning | F13: interaction | G13: measures | H13: factors | I13: context | J13: analyses | K13: target | L13: model
A14: 13 | B14: associated | C14: model | D14: development | E14: design | F14: design | G14: design | H14: investigated | I14: results | J14: cognitive | K14: functional | L14: inhibition
... A31: 30 | B31: model | C31: systems | D31: factor | E31: method | F31: model | G31: figures | H31: measures | I31: application | J31: stimulation | K31: resulting | L31: standard

Sheet cossim
B1: 0 | D1: 1 | E1: 2 | F1: 3 | G1: 4 | H1: 5 | I1: 6 | J1: 7 | K1: 8 | L1: 9 | M1: 10 | N1: 11 | O1: 12 | P1: 13 | Q1: 14 | R1: 15 | S1: 16 | T1: 17 | U1: 18 | V1: 19 | W1: 20 | X1: 21 | Y1: 22 | Z1: 23 | AA1: 24 | AB1: 25 | AC1: 26 | AD1: 27 | AE1: 28 | AF1: 29 | AG1: 30 | AH1: 31 | AI1: 32 | AJ1: 33 | AK1: 34 | AL1: 35 | AM1: 36 | AN1: 37 | AO1: 38 | AP1: 39 | AQ1: 40 | AR1: 41 | AS1: 42 | AT1: 43 | AU1: 44 | AV1: 45 | AW1: 46 | AX1: 47 | AY1: 48 | AZ1: 49 | BA1: 50 | BB1: 51 | BC1: 52 | BD1: 53 | BE1: 54 | BF1: 55 | BG1: 56 | BH1: 57 | BI1: 58 | BJ1: 59 | BK1: 60 | BL1: 61 | BM1: 62 | BN1: 63 | BO1: 64 | BP1: 65 | BQ1: 66 | BR1: 67 | BS1: 68 | BT1: 69 | BU1: 70 | BV1: 71 | BW1: 72 | BX1: 73 | BY1: 74 | BZ1: 75 | CA1: 76 | CB1: 77 | CC1: 78 | CD1: 79 | CE1: 80 | CF1: 81 | CG1: 82 | CH1: 83 | CI1: 84 | CJ1: 85 | CK1: 86 | CL1: 87 | CM1: 88 | CN1: 89 | CO1: 90 | CP1: 91 | CQ1: 92 | CR1: 93 | CS1: 94 | CT1: 95 | CU1: 96 | CV1: 97 | CW1: 98 | CX1: 99 | CY1: 100 | CZ1: 101 | DA1: 102 | DB1: 103 | DC1: 104 | DD1: 105 | DE1: 106
B2: 最大値 | D2: =MAX(D8:D1135) -> 0.47893363 | E2: =MAX(E8:E1135) -> 0.503583 | F2: =MAX(F8:F1135) -> 0.41257438 | G2: =MAX(G8:G1135) -> 0.5500667 | H2: =MAX(H8:H1135) -> 0.5232678 | I2: =MAX(I8:I1135) -> 0.45983332 | J2: =MAX(J8:J1135) -> 0.56289846 | K2: =MAX(K8:K1135) -> 0.9954481 | ... DE2: =MAX(DE8:DE1135) -> 0.5250086
B3: 最小値 | D3: =MIN(D8:D1135) -> -0.27967158 | E3: =MIN(E8:E1135) -> -0.174512 | F3: =MIN(F8:F1135) -> -0.1937299 | G3: =MIN(G8:G1135) -> -0.14987326 | H3: =MIN(H8:H1135) -> -0.16602077 | I3: =MIN(I8:I1135) -> -0.2553668 | J3: =MIN(J8:J1135) -> -0.15256062 | K3: =MIN(K8:K1135) -> 0.9627786 | ... DE3: =MIN(DE8:DE1135) -> -0.21795598
B4: 平均値 | D4: =AVERAGE(D8:D1135) -> 0.16378954 | E4: =AVERAGE(E8:E1135) -> 0.17603141 | F4: =AVERAGE(F8:F1135) -> 0.12010742 | G4: =AVERAGE(G8:G1135) -> 0.21897827 | H4: =AVERAGE(H8:H1135) -> 0.1718734 | I4: =AVERAGE(I8:I1135) -> 0.10615783 | J4: =AVERAGE(J8:J1135) -> 0.2211932 | K4: =AVERAGE(K8:K1135) -> 0.98107139 | ... DE4: =AVERAGE(DE8:DE1135) -> 0.12537214
B5: >=0.5の数 | D5: =COUNTIF(D8:D1135,">=0.5") -> 0 | E5: =COUNTIF(E8:E1135,">=0.5") -> 1 | F5: =COUNTIF(F8:F1135,">=0.5") -> 0 | G5: =COUNTIF(G8:G1135,">=0.5") -> 7 | H5: =COUNTIF(H8:H1135,">=0.5") -> 1 | I5: =COUNTIF(I8:I1135,">=0.5") -> 0 | J5: =COUNTIF(J8:J1135,">=0.5") -> 14 | K5: =COUNTIF(K8:K1135,">=0.5") -> 1128 | ... DE5: =COUNTIF(DE8:DE1135,">=0.5") -> 1
B6: 分散 | D6: =_xlfn.VAR.P(D8:D1135) -> 0.013310136 | E6: =_xlfn.VAR.P(E8:E1135) -> 0.014743741 | F6: =_xlfn.VAR.P(F8:F1135) -> 0.0096774282 | G6: =_xlfn.VAR.P(G8:G1135) -> 0.01320593 | H6: =_xlfn.VAR.P(H8:H1135) -> 0.012869503 | I6: =_xlfn.VAR.P(I8:I1135) -> 0.010252691 | J6: =_xlfn.VAR.P(J8:J1135) -> 0.015280493 | K6: =_xlfn.VAR.P(K8:K1135) -> 1.9193055e-05 | ... DE6: =_xlfn.VAR.P(DE8:DE1135) -> 0.0095463266
A7: 0 | B7: Source | D7: figure | E7: study | F7: analysis | G7: studies | H7: results | I7: model | J7: based | K7: research | L7: effect | M7: associated | N7: compared | O7: related | P7: effects | Q7: observed | R7: system | S7: development | T7: factors | U7: function | V7: models | W7: process | X7: work | Y7: method | Z7: performance | AA7: methods | AB7: factor | AC7: findings | AD7: target | AE7: figures | AF7: described | AG7: signaling | AH7: learning | AI7: considered | AJ7: analyzed | AK7: case | AL7: structure | AM7: evidence | AN7: functional | AO7: analyses | AP7: impact | AQ7: result | AR7: mechanisms | AS7: interaction | AT7: cognitive | AU7: standard | AV7: experimental | AW7: revealed | AX7: systems | AY7: features | AZ7: ability | BA7: design | BB7: formation | BC7: regulation | BD7: mechanism | BE7: flow | BF7: derived | BG7: influence | BH7: condition | BI7: detected | BJ7: developed | BK7: determined | BL7: association | BM7: comparison | BN7: form | BO7: effective | BP7: functions | BQ7: processing | BR7: subjects | BS7: defined | BT7: corresponding | BU7: proposed | BV7: interactions | BW7: consistent | BX7: limited | BY7: exposure | BZ7: understanding | CA7: measures | CB7: properties | CC7: affect | CD7: resulting | CE7: suggested | CF7: assessment | CG7: components | CH7: patterns | CI7: stimulation | CJ7: sequences | CK7: context | CL7: determine | CM7: solution | CN7: inhibition | CO7: contributions | CP7: investigated | CQ7: attention | CR7: suggesting | CS7: assessed | CT7: image | CU7: application | CV7: caused | CW7: generated | CX7: imaging | CY7: affected | CZ7: combined | DA7: pattern | DB7: baseline | DC7: availability | DD7: contributed | DE7: intervention | DF7: 平均 | DG7: 高平均ペア | DH7: main_交流度 | DI7: maintopic_jaccard | DJ7: participant_jaccard | DK7: rt_jaccard | DL7: rt_jaccard100 | DM7: rt_jaccard150 | DN7: m_jaccard_重み | DO7: p_jaccard_重み | DP7: section_jaccard50 | DQ7: section_jaccard100 | DR7: section_jaccard150 | DS7: section_jaccard50_new
A8: 1 | B8: Artificial Intelligence vs Computer Science | C8: 人工知能 vs コンピュータサイエンス | D8: -0.028446587 | E8: -0.0033611555 | F8: 0.22992162 | G8: 0.22113355 | H8: 0.22403453 | I8: 0.23065843 | J8: 0.2591172 | K8: 0.9807334 | L8: 0.2791975 | M8: 0.29054332 | N8: 0.30717185 | O8: 0.20106763 | P8: 0.31941354 | Q8: 0.23796833 | R8: -0.030984271 | S8: 0.017142246 | T8: 0.34669134 | U8: 0.21275072 | V8: 0.22063828 | W8: 0.16813892 | X8: 0.11087111 | Y8: 0.07864608 | Z8: 0.22421479 | AA8: 0.12326258 | AB8: 0.33360398 | AC8: 0.42222592 | AD8: 0.1243991 | AE8: 0.18000247 | AF8: 0.27186152 | AG8: 0.25122997 | AH8: 0.20087469 | AI8: 0.23136228 | AJ8: 0.12754571 | AK8: 0.1745943 | AL8: 0.22282705 | AM8: 0.34175542 | AN8: 0.36262676 | AO8: 0.2266446 | AP8: 0.2538279 | AQ8: 0.12946261 | AR8: 0.40092456 | AS8: 0.17080948 | AT8: 0.16718425 | AU8: 0.15073332 | AV8: 0.1232293 | AW8: -0.055271663 | AX8: 0.005748129 | AY8: 0.09767488 | AZ8: 0.9547707 | BA8: 0.14511505 | BB8: 0.1960721 | BC8: 0.078977734 | BD8: 0.15524456 | BE8: 0.29488012 | BF8: 0.27437013 | BG8: 0.31186455 | BH8: 0.09145996 | BI8: 0.20662127 | BJ8: 0.21611972 | BK8: 0.12563556 | BL8: 0.05038516 | BM8: 0.34777623 | BN8: 0.22761238 | BO8: 0.32315728 | BP8: 0.33737484 | BQ8: 0.11581312 | BR8: 0.17230092 | BS8: 0.14785488 | BT8: 0.29103252 | BU8: 0.18348144 | BV8: 0.1596187 | BW8: 0.10034721 | BX8: 0.26203614 | BY8: 0.19489992 | BZ8: 0.23371609 | CA8: 0.28954333 | CB8: 0.3428708 | CC8: 0.24366379 | CD8: 0.20712392 | CE8: 0.25287592 | CF8: 0.072181255 | CG8: 0.23751569 | CH8: 0.09993539 | CI8: 0.21041441 | CJ8: 0.26202065 | CK8: 0.06174937 | CL8: 0.20087248 | CM8: 0.2520336 | CN8: 0.3903585 | CO8: 0.11390283 | CP8: 0.23602271 | CQ8: 0.060259663 | CR8: 0.19232792 | CS8: 0.32362524 | CT8: 0.12217722 | CU8: 0.12589212 | CV8: 0.19094664 | CW8: 0.15157129 | CX8: 0.15362917 | CY8: 0.1575969 | CZ8: 0.38096574 | DA8: 0.10242216 | DB8: 0.26719582 | DC8: 0.96858287 | DD8: 0.22250399 | DE8: 0.09616714 | DF8: =AVERAGE(D8:J8,L8:AY8,BA8:DB8,DD8:DE8) -> 0.1982505 | DG8: =IF(DF8>=0.25,1,0) -> 0 | DH8: 0.01787318 | DI8: =VLOOKUP(B8,owner_jaccard!$C$1:$E$1128,3,FALSE) -> 0.33333333 | DJ8: =VLOOKUP(B8,partic_jaccard!$C$1:$E$1128,3,FALSE) -> 0.26086957 | DK8: =VLOOKUP(B8,rtword_jaccard!$C$1:$E$1128,3,FALSE) -> 0.44927536 | DL8: =VLOOKUP(B8,rtword_jaccard!$C$1:$F$1128,4,FALSE) -> 0.58730159 | DM8: =VLOOKUP(B8,rtword_jaccard!$C$1:$G$1128,5,FALSE) -> 0.54639175 | DN8: =VLOOKUP(B8,owner_j_重み付き!$C$1:$E$1128,3) -> 0.0335 | DO8: =VLOOKUP(B8,part_j_重み付き!$C$1:$E$1128,3,FALSE) -> 0.1326 | DP8: =VLOOKUP(B8,journalsection_jaccard!$C$2:$E$1129,3,FALSE) -> 0.53846154 | DQ8: =VLOOKUP(B8,journalsection_jaccard!$C$2:$F$1129,4,FALSE) -> 0.4084507 | DR8: =VLOOKUP(B8,journalsection_jaccard!$C$2:$G$1129,5,FALSE) -> 0.36986301 | DS8: =VLOOKUP(B8,journalsection_jaccard!$C$2:$H$1129,6,FALSE) -> 0.2195122
A9: 2 | B9: Artificial Intelligence vs Psychology | C9: 人工知能 vs 心理学 | D9: 0.18046255 | E9: 0.25162423 | F9: 0.1757238 | G9: 0.17586961 | H9: 0.08675858 | I9: 0.277539 | J9: 0.15200296 | K9: 0.9795682 | L9: 0.06287314 | M9: 0.22242323 | N9: 0.20749998 | O9: 0.05557556 | P9: 0.058957968 | Q9: 0.23856622 | R9: 0.084158234 | S9: 0.22001596 | T9: 0.18543822 | U9: 0.2346844 | V9: 0.27243468 | W9: 0.21440092 | X9: 0.18212496 | Y9: 0.029209556 | Z9: 0.30248898 | AA9: 0.047650244 | AB9: 0.08304028 | AC9: 0.09340218 | AD9: 0.34100685 | AE9: 0.018772855 | AF9: 0.28814492 | AG9: 0.15603799 | AH9: 0.19488966 | AI9: 0.47533056 | AJ9: 0.21298434 | AK9: 0.24007598 | AL9: 0.21375744 | AM9: 0.0954315 | AN9: 0.20043597 | AO9: 0.1813792 | AP9: 0.35279226 | AQ9: 0.20466182 | AR9: 0.16831172 | AS9: 0.02750745 | AT9: 0.08533338 | AU9: 0.15351713 | AV9: 0.40288484 | AW9: 0.18460856 | AX9: 0.15393335 | AY9: 0.36905843 | AZ9: 0.9694565 | BA9: 0.13059965 | BB9: 0.17169717 | BC9: 0.12495294 | BD9: 0.037502766 | BE9: 0.11802436 | BF9: 0.357698 | BG9: 0.2338055 | BH9: 0.11135751 | BI9: 0.24962358 | BJ9: 0.33796343 | BK9: 0.3223002 | BL9: 0.32899848 | BM9: 0.036236737 | BN9: 0.15618849 | BO9: 0.25641808 | BP9: 0.25657168 | BQ9: 0.020999676 | BR9: 0.3309288 | BS9: 0.31001043 | BT9: 0.2800148 | BU9: 0.31442294 | BV9: 0.07999064 | BW9: 0.178549 | BX9: 0.38650447 | BY9: 0.13963184 | BZ9: -0.031501133 | CA9: 0.38657013 | CB9: 0.3262807 | CC9: 0.057119463 | CD9: 0.37897074 | CE9: 0.30405554 | CF9: 0.1216512 | CG9: 0.27925915 | CH9: 0.17425717 | CI9: 0.19801234 | CJ9: 0.30317882 | CK9: 0.018101769 | CL9: 0.21934782 | CM9: 0.20552413 | CN9: 0.3017428 | CO9: -0.04353534 | CP9: 0.29318145 | CQ9: 0.12427708 | CR9: 0.36873955 | CS9: 0.3233452 | CT9: 0.080862306 | CU9: 0.075943366 | CV9: 0.3173828 | CW9: 0.1193781 | CX9: 0.14939024 | CY9: 0.33990335 | CZ9: 0.29623595 | DA9: 0.049197942 | DB9: 0.32352972 | DC9: 0.97169363 | DD9: 0.2751671 | DE9: 0.08342491 | DF9: =AVERAGE(D9:J9,L9:AY9,BA9:DB9,DD9:DE9) -> 0.19908512 | DG9: =IF(DF9>=0.25,1,0) -> 0 | DH9: 0.015964629 | DI9: =VLOOKUP(B9,owner_jaccard!$C$1:$E$1128,3,FALSE) -> 0.24074074 | DJ9: =VLOOKUP(B9,partic_jaccard!$C$1:$E$1128,3,FALSE) -> 0.47058824 | DK9: =VLOOKUP(B9,rtword_jaccard!$C$1:$E$1128,3,FALSE) -> 0.2195122 | DL9: =VLOOKUP(B9,rtword_jaccard!$C$1:$F$1128,4,FALSE) -> 0.28205128 | DM9: =VLOOKUP(B9,rtword_jaccard!$C$1:$G$1128,5,FALSE) -> 0.32743363 | DN9: =VLOOKUP(B9,owner_j_重み付き!$C$1:$E$1128,3) -> 0.0025 | DO9: =VLOOKUP(B9,part_j_重み付き!$C$1:$E$1128,3,FALSE) -> 0.0018 | DP9: =VLOOKUP(B9,journalsection_jaccard!$C$2:$E$1129,3,FALSE) -> 0.61290323 | DQ9: =VLOOKUP(B9,journalsection_jaccard!$C$2:$F$1129,4,FALSE) -> 0.36054422 | DR9: =VLOOKUP(B9,journalsection_jaccard!$C$2:$G$1129,5,FALSE) -> 0.33333333 | DS9: =VLOOKUP(B9,journalsection_jaccard!$C$2:$H$1129,6,FALSE) -> 0.20481928
A10: 3 | B10: Artificial Intelligence vs Aging Neuroscience | C10: 人工知能と老化神経科学の最前線 | D10: 0.19391279 | E10: 0.26779866 | F10: 0.14499079 | G10: 0.048386026 | H10: 0.19368936 | I10: 0.13334793 | J10: 0.2144582 | K10: 0.9775029 | L10: 0.18110019 | M10: 0.13506697 | N10: 0.24586672 | O10: 0.18108714 | P10: 0.2747221 | Q10: 0.2066418 | R10: 0.12665328 | S10: -0.009975265 | T10: 0.17593096 | U10: -0.05315222 | V10: 0.05301799 | W10: 0.20990588 | X10: 0.15584491 | Y10: 0.024865625 | Z10: 0.21488604 | AA10: 0.049113147 | AB10: 0.16084805 | AC10: 0.33339998 | AD10: 0.20064406 | AE10: 0.14496623 | AF10: 0.24924211 | AG10: -0.024887737 | AH10: 0.061611984 | AI10: 0.38234946 | AJ10: 0.039791744 | AK10: 0.3236608 | AL10: 0.07836455 | AM10: 0.25200903 | AN10: 0.1946201 | AO10: 0.21290824 | AP10: 0.15952109 | AQ10: 0.17921473 | AR10: 0.3480207 | AS10: 0.044316325 | AT10: -0.06670053 | AU10: 0.25467908 | AV10: 0.12987065 | AW10: 0.15549374 | AX10: 0.042087197 | AY10: 0.34265924 | AZ10: 0.9652467 | BA10: -0.12654158 | BB10: 0.019804303 | BC10: 0.24924096 | BD10: 0.23533127 | BE10: 0.09086441 | BF10: 0.10352984 | BG10: 0.16826156 | BH10: -0.03364272 | BI10: 0.18085286 | BJ10: 0.22155274 | BK10: 0.31950414 | BL10: 0.14151263 | BM10: 0.23616269 | BN10: 0.23253734 | BO10: 0.20288265 | BP10: 0.06341934 | BQ10: 0.13987994 | BR10: 0.23403701 | BS10: 0.26904377 | BT10: 0.3710032 | BU10: 0.09530684 | BV10: 0.012973571 | BW10: 0.1866654 | BX10: 0.26371577 | BY10: 0.2704512 | BZ10: 0.031614274 | CA10: 0.15638325 | CB10: 0.14420521 | CC10: 0.06692569 | CD10: 0.2047846 | CE10: 0.17692806 | CF10: 0.19491102 | CG10: 0.37188673 | CH10: 0.11938927 | CI10: 0.17003252 | CJ10: 0.32350227 | CK10: 0.17443384 | CL10: 0.2423821 | CM10: 0.042381078 | CN10: 0.11966252 | CO10: -0.037349805 | CP10: 0.3084231 | CQ10: 0.013330068 | CR10: 0.21265829 | CS10: 0.2484294 | CT10: 0.0049993 | CU10: 0.25526997 | CV10: 0.25602704 | CW10: -0.035052128 | CX10: 0.072111174 | CY10: 0.2791761 | CZ10: 0.31596887 | DA10: 0.21825278 | DB10: 0.14256628 | DC10: 0.97308266 | DD10: 0.31944054 | DE10: 0.13331355 | DF10: =AVERAGE(D10:J10,L10:AY10,BA10:DB10,DD10:DE10) -> 0.16468142 | DG10: =IF(DF10>=0.25,1,0) -> 0 | DH10: 0 | DI10: =VLOOKUP(B10,owner_jaccard!$D$1:$E$1128,2,FALSE) -> 0.22857143 | DJ10: =VLOOKUP(B10,partic_jaccard!$D$1:$E$1128,2,FALSE) -> 0.42857143 | DK10: =VLOOKUP(B10,rtword_jaccard!$D$1:$E$1128,2,FALSE) -> 0.12359551 | DL10: =VLOOKUP(B10,rtword_jaccard!$D$1:$F$1128,3,FALSE) -> 0.16959064 | DM10: =VLOOKUP(B10,rtword_jaccard!$D$1:$G$1128,4,FALSE) -> 0.20481928 | DN10: =VLOOKUP(B10,owner_j_重み付き!$C$1:$E$1128,3) -> 0.0092 | DO10: =VLOOKUP(B10,part_j_重み付き!$D$1:$E$1128,2,FALSE) -> 0.0733 | DP10: =journalsection_jaccard!E3 -> 0.2987013 | DQ10: =journalsection_jaccard!F3 -> 0.32450331 | DR10: =journalsection_jaccard!G3 -> 0.2605042 | DS10: 0.13636364
A11: 4 | B11: Artificial Intelligence vs Applied Mathematics and Statistics | C11: 人工知能と応用数学・統計学の最先端 | D11: 0.23362942 | E11: -0.012000329 | F11: -0.17664579 | G11: 0.03647395 | H11: 0.16156515 | I11: 0.030141214 | J11: 0.11248044 | K11: 0.9834303 | L11: 0.16777721 | M11: -0.07598025 | N11: 0.25540236 | O11: 0.10049295 | P11: -0.18164547 | Q11: 0.089574054 | R11: 0.06780051 | S11: 0.12137341 | T11: 0.28977212 | U11: 0.19991206 | V11: 0.08374342 | W11: 0.1466002 | X11: 0.03764076 | Y11: 0.018572124 | Z11: 0.0849191 | AA11: -0.0016192896 | AB11: 0.1663724 | AC11: 0.10620742 | AD11: -0.021323169 | AE11: -0.009740454 | AF11: 0.23843884 | AG11: 0.35463625 | AH11: -0.10071967 | AI11: 0.30794266 | AJ11: 0.022447567 | AK11: 0.18894573 | AL11: 0.03373772 | AM11: 0.156354 | AN11: 0.28856736 | AO11: -0.09479361 | AP11: 0.14357989 | AQ11: 0.18167992 | AR11: 0.41504636 | AS11: 0.12168044 | AT11: 0.07703947 | AU11: 0.08704131 | AV11: -0.058530137 | AW11: -0.040537525 | AX11: 0.068202816 | AY11: 0.15627632 | AZ11: 0.9382193 | BA11: 0.15754013 | BB11: 0.04753322 | BC11: 0.18150301 | BD11: 0.27534673 | BE11: 0.1005438 | BF11: 0.23097363 | BG11: 0.31649983 | BH11: 0.13123666 | BI11: 0.19707893 | BJ11: 0.19713359 | BK11: 0.3381152 | BL11: 0.08351894 | BM11: 0.20721842 | BN11: 0.20305963 | BO11: 0.28365257 | BP11: 0.23859134 | BQ11: 0.0017801591 | BR11: 0.065854594 | BS11: 0.13319801 | BT11: 0.06192957 | BU11: 0.16437586 | BV11: 0.17052168 | BW11: 0.17751907 | BX11: 0.17501654 | BY11: 0.25196457 | BZ11: 0.013856807 | CA11: 0.29574198 | CB11: 0.074554645 | CC11: 0.24378015 | CD11: 0.10158709 | CE11: 0.27383947 | CF11: 0.13102162 | CG11: 0.31177428 | CH11: 0.019665679 | CI11: 0.2630453 | CJ11: 0.24283628 | CK11: 0.25738078 | CL11: 0.16392177 | CM11: 0.1588571 | CN11: 0.3508804 | CO11: -0.045849375 | CP11: 0.2563111 | CQ11: 0.026156897 | CR11: 0.23558885 | CS11: 0.29077953 | CT11: 0.18810801 | CU11: 0.10449753 | CV11: 0.26696151 | CW11: 0.03465294 | CX11: 0.2873524 | CY11: 0.31538287 | CZ11: 0.2195763 | DA11: 0.09120247 | DB11: 0.3712073 | DC11: 0.95845157 | DD11: 0.22093327 | DE11: 0.19113934 | DF11: =AVERAGE(D11:J11,L11:AY11,BA11:DB11,DD11:DE11) -> 0.14492215 | DG11: =IF(DF11>=0.25,1,0) -> 0 | DH11: 0.007923113 | DI11: =VLOOKUP(B11,owner_jaccard!$D$1:$E$1128,2,FALSE) -> 0.38461538 | DJ11: =VLOOKUP(B11,partic_jaccard!$D$1:$E$1128,2,FALSE) -> 0.2173913 | DK11: =VLOOKUP(B11,rtword_jaccard!$D$1:$E$1128,2,FALSE) -> 0.25 | DL11: =VLOOKUP(B11,rtword_jaccard!$D$1:$F$1128,3,FALSE) -> 0.34228188 | DM11: =VLOOKUP(B11,rtword_jaccard!$D$1:$G$1128,4,FALSE) -> 0.36986301 | DN11: =VLOOKUP(B11,owner_j_重み付き!$C$1:$E$1128,3) -> 0.0092 | DO11: =VLOOKUP(B11,part_j_重み付き!$D$1:$E$1128,2,FALSE) -> 0.0794 | DP11: =VLOOKUP(B11,journalsection_jaccard!$D$2:$E$1129,2,FALSE) -> 0.47058824 | DQ11: =VLOOKUP(B11,journalsection_jaccard!$D$2:$F$1129,3,FALSE) -> 0.47058824 | DR11: =VLOOKUP(B11,journalsection_jaccard!$D$2:$G$1129,4,FALSE) -> 0.38248848 | DS11: =VLOOKUP(B11,journalsection_jaccard!$D$2:$H$1129,5,FALSE) -> 0.25
A12: 5 | B12: Artificial Intelligence vs Astronomy and Space Sciences | C12: 人工知能と天文学および宇宙科学の最先端 | D12: 0.16928482 | E12: 0.05854011 | F12: 0.26694044 | G12: 0.16959754 | H12: -0.012636899 | I12: 0.14229786 | J12: 0.14360538 | K12: 0.97755784 | L12: 0.24947889 | M12: 0.17267159 | N12: 0.16319312 | O12: 0.170077 | P12: 0.027703568 | Q12: 0.18150498 | R12: 0.03364794 | S12: 0.1673368 | T12: 0.2883434 | U12: 0.18933277 | V12: -0.015239696 | W12: 0.18020706 | X12: 0.013987163 | Y12: 0.3339124 | Z12: 0.21477701 | AA12: 0.25468877 | AB12: 0.21325544 | AC12: 0.10585099 | AD12: -0.060502507 | AE12: 0.14438634 | AF12: 0.20148405 | AG12: 0.4372296 | AH12: -0.024513027 | AI12: 0.3830166 | AJ12: 0.077730805 | AK12: 0.14578429 | AL12: 0.11631851 | AM12: 0.2211208 | AN12: 0.13042215 | AO12: 0.23494248 | AP12: 0.08810682 | AQ12: 0.23639226 | AR12: 0.22494338 | AS12: 0.18035181 | AT12: 0.1046719 | AU12: 0.2556848 | AV12: 0.1687371 | AW12: 0.058510967 | AX12: -0.022542994 | AY12: 0.06388398 | AZ12: 0.9138744 | BA12: 0.17610456 | BB12: -0.120579 | BC12: 0.31684172 | BD12: 0.22664839 | BE12: 0.16525532 | BF12: 0.19762163 | BG12: 0.25051877 | BH12: 0.34817585 | BI12: 0.16700895 | BJ12: 0.19504933 | BK12: 0.19890274 | BL12: 0.0052422397 | BM12: 0.28478265 | BN12: 0.23518722 | BO12: 0.20498826 | BP12: 0.23953359 | BQ12: 0.21533455 | BR12: 0.009945581 | BS12: 0.13481782 | BT12: 0.15693013 | BU12: 0.08456669 | BV12: 0.1638729 | BW12: 0.19121732 | BX12: 0.41744095 | BY12: 0.27788785 | BZ12: -0.014891177 | CA12: 0.45088345 | CB12: -0.06472452 | CC12: 0.320332 | CD12: 0.1819926 | CE12: 0.06690879 | CF12: 0.17383072 | CG12: 0.1847848 | CH12: 0.13790207 | CI12: 0.2730715 | CJ12: 0.20825501 | CK12: 0.06763546 | CL12: 0.30453262 | CM12: 0.072315544 | CN12: 0.36409065 | CO12: 0.1230242 | CP12: 0.2637402 | CQ12: 0.1684405 | CR12: 0.26216897 | CS12: 0.2930958 | CT12: 0.13680877 | CU12: 0.088879235 | CV12: 0.24347791 | CW12: 0.12074491 | CX12: 0.11377944 | CY12: 0.24892622 | CZ12: 0.21471436 | DA12: 0.2013071 | DB12: 0.2850128 | DC12: 0.95646614 | DD12: 0.19550015 | DE12: 0.10573417 | DF12: =AVERAGE(D12:J12,L12:AY12,BA12:DB12,DD12:DE12) -> 0.17266106 | DG12: =IF(DF12>=0.25,1,0) -> 0 | DH12: 0 | DI12: =VLOOKUP(B12,owner_jaccard!$C$1:$E$1128,3,FALSE) -> 0.13636364 | DJ12: =VLOOKUP(B12,partic_jaccard!$C$1:$E$1128,3,FALSE) -> 0.090909091 | DK12: =VLOOKUP(B12,rtword_jaccard!$C$1:$E$1128,3,FALSE) -> 0.12359551 | DL12: =VLOOKUP(B12,rtword_jaccard!$C$1:$F$1128,4,FALSE) -> 0.1627907 | DM12: =VLOOKUP(B12,rtword_jaccard!$C$1:$G$1128,5,FALSE) -> 0.19521912 | DN12: =VLOOKUP(B12,owner_j_重み付き!$C$1:$E$1128,3) -> 0.0037 | DO12: =VLOOKUP(B12,part_j_重み付き!$C$1:$E$1128,3,FALSE) -> 0.0127 | DP12: =VLOOKUP(B12,journalsection_jaccard!$C$2:$E$1129,3,FALSE) -> 0.49253731 | DQ12: =VLOOKUP(B12,journalsection_jaccard!$C$2:$F$1129,4,FALSE) -> 0.33333333 | DR12: =VLOOKUP(B12,journalsection_jaccard!$C$2:$G$1129,5,FALSE) -> 0.3215859 | DS12: =VLOOKUP(B12,journalsection_jaccard!$C$2:$H$1129,6,FALSE) -> 0.11111111
A13: 6 | B13: Artificial Intelligence vs Big Data | C13: 人工知能とビッグデータのフロンティア | D13: 0.1863641 | E13: 0.28676382 | F13: 0.011533973 | G13: 0.20901316 | H13: 0.14242636 | I13: 0.1259258 | J13: 0.026903598 | K13: 0.986467 | L13: 0.15879595 | M13: 0.21042256 | N13: 0.23924121 | O13: 0.12446354 | P13: 0.022704918 | Q13: 0.19477406 | R13: 0.093596466 | S13: 0.065988004 | T13: 0.19717328 | U13: 0.2220414 | V13: -0.015898066 | W13: 0.0024184207 | X13: 0.23032117 | Y13: 0.16237006 | Z13: 0.084248796 | AA13: 0.045275122 | AB13: 0.2287512 | AC13: 0.29699558 | AD13: 0.1847766 | AE13: 0.26644552 | AF13: 0.18899944 | AG13: 0.27403766 | AH13: -0.29030037 | AI13: 0.26829484 | AJ13: 0.13113034 | AK13: 0.04868713 | AL13: 0.12050153 | AM13: 0.23981419 | AN13: 0.31779552 | AO13: -0.0037587478 | AP13: 0.11797584 | AQ13: 0.14655273 | AR13: 0.40292808 | AS13: 0.0035726703 | AT13: 0.18690082 | AU13: 0.20997746 | AV13: 0.19506852 | AW13: 0.014782637 | AX13: 0.062160797 | AY13: 0.1754112 | AZ13: 0.9350696 | BA13: 0.23431423 | BB13: 0.15533556 | BC13: 0.18952802 | BD13: 0.34591207 | BE13: 0.2909973 | BF13: 0.32921872 | BG13: 0.34151044 | BH13: 0.13440785 | BI13: 0.24734367 | BJ13: 0.29039383 | BK13: 0.26055998 | BL13: 0.17515106 | BM13: 0.03989168 | BN13: 0.15852264 | BO13: 0.17521726 | BP13: 0.2733672 | BQ13: 0.1479303 | BR13: 0.05682026 | BS13: 0.17104094 | BT13: 0.19563048 | BU13: 0.07774767 | BV13: 0.07974944 | BW13: 0.2636723 | BX13: 0.33841008 | BY13: 0.18568613 | BZ13: 0.26460946 | CA13: 0.21834074 | CB13: 0.18750502 | CC13: 0.3630092 | CD13: 0.14674439 | CE13: 0.23052584 | CF13: 0.14956138 | CG13: 0.33742982 | CH13: 0.11499904 | CI13: 0.13191736 | CJ13: 0.12591983 | CK13: 0.24043085 | CL13: 0.15162188 | CM13: 0.3527445 | CN13: 0.21649913 | CO13: 0.10204168 | CP13: 0.3278445 | CQ13: 0.04150067 | CR13: 0.014889478 | CS13: 0.3090865 | CT13: 0.13662192 | CU13: 0.16147596 | CV13: 0.31449297 | CW13: 0.23877287 | CX13: 0.16985688 | CY13: 0.17754152 | CZ13: 0.28276026 | DA13: 0.159387 | DB13: 0.14811704 | DC13: 0.97031736 | DD13: 0.14919208 | DE13: 0.1743962 | DF13: =AVERAGE(D13:J13,L13:AY13,BA13:DB13,DD13:DE13) -> 0.17585014 | DG13: =IF(DF13>=0.25,1,0) -> 0 | DH13: 0.19076815 | DI13: =VLOOKUP(B13,owner_jaccard!$C$1:$E$1128,3,FALSE) -> 0.23809524 | DJ13: =VLOOKUP(B13,partic_jaccard!$C$1:$E$1128,3,FALSE) -> 0.33333333 | DK13: =VLOOKUP(B13,rtword_jaccard!$C$1:$E$1128,3,FALSE) -> 0.49253731 | DL13: =VLOOKUP(B13,rtword_jaccard!$C$1:$F$1128,4,FALSE) -> 0.5037594 | DM13: =VLOOKUP(B13,rtword_jaccard!$C$1:$G$1128,5,FALSE) -> 0.53846154 | DN13: =VLOOKUP(B13,owner_j_重み付き!$C$1:$E$1128,3) -> 0.0854 | DO13: =VLOOKUP(B13,part_j_重み付き!$C$1:$E$1128,3,FALSE) -> 0.082 | DP13: =VLOOKUP(B13,journalsection_jaccard!$C$2:$E$1129,3,FALSE) -> 0.63934426 | DQ13: =VLOOKUP(B13,journalsection_jaccard!$C$2:$F$1129,4,FALSE) -> 0.5625 | DR13: =VLOOKUP(B13,journalsection_jaccard!$C$2:$G$1129,5,FALSE) -> 0.44927536 | DS13: =VLOOKUP(B13,journalsection_jaccard!$C$2:$H$1129,6,FALSE) -> 0.4084507
A14: 7 | B14: Artificial Intelligence vs Bioengineering and Biotechnology | C14: 人工知能とバイオエンジニアリングおよびバイオテクノロジーの最先端 | D14: 0.26127046 | E14: 0.1668042 | F14: 0.2043077 | G14: 0.15099867 | H14: 0.2324244 | I14: 0.17402673 | J14: 0.16352737 | K14: 0.9718912 | L14: 0.14034401 | M14: 0.093479395 | N14: 0.17497857 | O14: 0.020774234 | P14: 0.03546281 | Q14: 0.25006032 | R14: -0.0015923077 | S14: 0.35363114 | T14: 0.18131661 | U14: 0.1479511 | V14: 0.10294653 | W14: 0.36560702 | X14: 0.31812608 | Y14: 0.17507392 | Z14: 0.14500262 | AA14: 0.03001782 | AB14: 0.25986302 | AC14: 0.4050372 | AD14: 0.029124498 | AE14: 0.33001202 | AF14: 0.090624064 | AG14: 0.06791258 | AH14: 0.09083794 | AI14: 0.20624197 | AJ14: 0.10814108 | AK14: 0.2183636 | AL14: 0.041139446 | AM14: 0.31452253 | AN14: 0.2853991 | AO14: 0.2716395 | AP14: 0.059147805 | AQ14: 0.24352196 | AR14: 0.17256884 | AS14: 0.16129206 | AT14: 0.017946078 | AU14: 0.11104419 | AV14: 0.17881285 | AW14: 0.13876136 | AX14: 0.052388266 | AY14: 0.35064688 | AZ14: 0.9583209 | BA14: 0.049610175 | BB14: 0.23276554 | BC14: 0.27995503 | BD14: 0.18105492 | BE14: 0.23669939 | BF14: 0.15986173 | BG14: 0.25374457 | BH14: 0.069293246 | BI14: 0.19561964 | BJ14: 0.1853895 | BK14: 0.20098428 | BL14: 0.1432612 | BM14: 0.1654074 | BN14: 0.10570464 | BO14: 0.38474107 | BP14: 0.22077091 | BQ14: 0.055143427 | BR14: 0.1697809 | BS14: 0.20588987 | BT14: 0.3560527 | BU14: 0.2813674 | BV14: 0.20954885 | BW14: 0.078031346 | BX14: 0.20589982 | BY14: 0.07358923 | BZ14: 0.29980007 | CA14: 0.33010885 | CB14: 0.09860673 | CC14: 0.16715597 | CD14: 0.19879493 | CE14: 0.1775916 | CF14: 0.30399847 | CG14: 0.29456466 | CH14: 0.08570064 | CI14: -0.037034873 | CJ14: 0.3422783 | CK14: 0.16858311 | CL14: 0.20337802 | CM14: 0.08476944 | CN14: 0.10076866 | CO14: 0.29086524 | CP14: 0.23290718 | CQ14: 0.16280924 | CR14: 0.28169784 | CS14: 0.32619324 | CT14: 0.015471916 | CU14: 0.13648659 | CV14: 0.1809308 | CW14: 0.08537459 | CX14: 0.089780085 | CY14: 0.0725746 | CZ14: 0.20152757 | DA14: 0.055367757 | DB14: 0.19530925 | DC14: 0.9647091 | DD14: 0.2664129 | DE14: 0.0507233 | DF14: =AVERAGE(D14:J14,L14:AY14,BA14:DB14,DD14:DE14) -> 0.17723487 | DG14: =IF(DF14>=0.25,1,0) -> 0 | DH14: 0 | DI14: =VLOOKUP(B14,owner_jaccard!$C$1:$E$1128,3,FALSE) -> 0.24390244 | DJ14: =VLOOKUP(B14,partic_jaccard!$C$1:$E$1128,3,FALSE) -> 0.36111111 | DK14: =VLOOKUP(B14,rtword_jaccard!$C$1:$E$1128,3,FALSE) -> 0.19047619 | DL14: =VLOOKUP(B14,rtword_jaccard!$C$1:$F$1128,4,FALSE) -> 0.27388535 | DM14: =VLOOKUP(B14,rtword_jaccard!$C$1:$G$1128,5,FALSE) -> 0.28205128 | DN14: =VLOOKUP(B14,owner_j_重み付き!$C$1:$E$1128,3) -> 0.0077 | DO14: =VLOOKUP(B14,part_j_重み付き!$C$1:$E$1128,3,FALSE) -> 0.0376 | DP14: =VLOOKUP(B14,journalsection_jaccard!$C$2:$E$1129,3,FALSE) -> 0.25 | DQ14: =VLOOKUP(B14,journalsection_jaccard!$C$2:$F$1129,4,FALSE) -> 0.31578947 | DR14: =VLOOKUP(B14,journalsection_jaccard!$C$2:$G$1129,5,FALSE) -> 0.31578947 | DS14: =VLOOKUP(B14,journalsection_jaccard!$C$2:$H$1129,6,FALSE) -> 0.19047619
A15: 8 | B15: Artificial Intelligence vs Cardiovascular Medicine | C15: 人工知能と心臓血管医学の最先端 | D15: 0.077852644 | E15: 0.2631343 | F15: 0.33474997 | G15: 0.11873299 | H15: 0.02023854 | I15: 0.03723992 | J15: 0.335429 | K15: 0.9768717 | L15: 0.37467912 | M15: 0.2170772 | N15: 0.29946363 | O15: 0.09316351 | P15: 0.22431932 | Q15: 0.2033864 | R15: -0.04388539 | S15: 0.026724324 | T15: 0.3624577 | U15: 0.10034763 | V15: -0.052416332 | W15: -0.0035242618 | X15: 0.2803386 | Y15: 0.045859944 | Z15: 0.23396333 | AA15: 0.032476496 | AB15: 0.21754764 | AC15: 0.20949538 | AD15: 0.046529654 | AE15: 0.037982114 | AF15: 0.2622988 | AG15: 0.11842778 | AH15: 0.056941494 | AI15: 0.326975 | AJ15: 0.22819813 | AK15: 0.3311225 | AL15: 0.085355885 | AM15: 0.15873669 | AN15: 0.15156452 | AO15: 0.2828789 | AP15: 0.24689756 | AQ15: 0.12357905 | AR15: 0.26665625 | AS15: 0.1396338 | AT15: -0.24181505 | AU15: 0.2156302 | AV15: 0.07113124 | AW15: 0.08378294 | AX15: 0.09614716 | AY15: 0.33211008 | AZ15: 0.9549556 | BA15: 0.09096491 | BB15: -0.07986991 | BC15: 0.19120564 | BD15: 0.2226668 | BE15: 0.22552164 | BF15: 0.252306 | BG15: 0.29231182 | BH15: 0.01695536 | BI15: 0.28996137 | BJ15: 0.2708613 | BK15: 0.24162637 | BL15: 0.15059927 | BM15: 0.32528874 | BN15: 0.246628 | BO15: 0.3169411 | BP15: 0.13186117 | BQ15: 0.1968502 | BR15: 0.1673151 | BS15: 0.15132153 | BT15: 0.2769115 | BU15: 0.20475262 | BV15: 0.22181742 | BW15: 0.20370337 | BX15: 0.39980993 | BY15: 0.13725135 | BZ15: 0.07756057 | CA15: 0.20454061 | CB15: 0.224457 | CC15: 0.27018937 | CD15: 0.36961567 | CE15: 0.12667374 | CF15: 0.25170687 | CG15: 0.28098735 | CH15: 0.19909476 | CI15: 0.21730764 | CJ15: 0.24694839 | CK15: 0.13742888 | CL15: 0.34076074 | CM15: 0.16295971 | CN15: 0.2043942 | CO15: 0.058601033 | CP15: 0.35066348 | CQ15: 0.19037864 | CR15: 0.17760284 | CS15: 0.33004346 | CT15: 0.060962666 | CU15: -0.025054146 | CV15: 0.2522777 | CW15: 0.15405731 | CX15: 0.20947178 | CY15: 0.3063885 | CZ15: 0.23209506 | DA15: 0.08748854 | DB15: 0.12399343 | DC15: 0.96938765 | DD15: 0.17128077 | DE15: 0.040072408 | DF15: =AVERAGE(D15:J15,L15:AY15,BA15:DB15,DD15:DE15) -> 0.18068085 | DG15: =IF(DF15>=0.25,1,0) -> 0 | DH15: 0 | DI15: =VLOOKUP(B15,owner_jaccard!$C$1:$E$1128,3,FALSE) -> 0.23076923 | DJ15: =VLOOKUP(B15,partic_jaccard!$C$1:$E$1128,3,FALSE) -> 0.37931034 | DK15: =VLOOKUP(B15,rtword_jaccard!$C$1:$E$1128,3,FALSE) -> 0.14942529 | DL15: =VLOOKUP(B15,rtword_jaccard!$C$1:$F$1128,4,FALSE) -> 0.19047619 | DM15: =VLOOKUP(B15,rtword_jaccard!$C$1:$G$1128,5,FALSE) -> 0.2244898 | DN15: =VLOOKUP(B15,owner_j_重み付き!$C$1:$E$1128,3) -> 0.0044 | DO15: =VLOOKUP(B15,part_j_重み付き!$C$1:$E$1128,3,FALSE) -> 0.057 | DP15: =VLOOKUP(B15,journalsection_jaccard!$C$2:$E$1129,3,FALSE) -> 0.53846154 | DQ15: =VLOOKUP(B15,journalsection_jaccard!$C$2:$F$1129,4,FALSE) -> 0.33333333 | DR15: =VLOOKUP(B15,journalsection_jaccard!$C$2:$G$1129,5,FALSE) -> 0.31004367 | DS15: =VLOOKUP(B15,journalsection_jaccard!$C$2:$H$1129,6,FALSE) -> 0.13636364
A16: 9 | B16: Artificial Intelligence vs Cell and Developmental Biology | C16: 人工知能と細胞生物学および発生生物学の最先端 | D16: 0.17863017 | E16: 0.21422693 | F16: 0.0684752 | G16: 0.17826472 | H16: 0.13084356 | I16: 0.11413652 | J16: 0.19086222 | K16: 0.97693413 | L16: 0.17610604 | M16: 0.021885864 | N16: 0.2119793 | O16: 0.06902598 | P16: 0.18886606 | Q16: 0.24319367 | R16: 0.033444025 | S16: 0.11949958 | T16: 0.17475274 | U16: -0.018244438 | V16: 0.13066585 | W16: 0.044516623 | X16: 0.13994792 | Y16: -0.0029625993 | Z16: 0.12857854 | AA16: 0.038795773 | AB16: 0.20794846 | AC16: 0.27088058 | AD16: 0.018389672 | AE16: -0.12764122 | AF16: 0.11231037 | AG16: -0.11539369 | AH16: 0.20604913 | AI16: 0.27368858 | AJ16: 0.21068656 | AK16: 0.1092598 | AL16: 0.1268274 | AM16: 0.2931026 | AN16: 0.13000086 | AO16: 0.12438611 | AP16: 0.33316314 | AQ16: 0.17844306 | AR16: 0.016003136 | AS16: 0.08738175 | AT16: 0.035918362 | AU16: 0.19448806 | AV16: 0.091631584 | AW16: 0.16455151 | AX16: 0.03430997 | AY16: 0.38021004 | AZ16: 0.9664866 | BA16: 0.0732889 | BB16: -0.0013373817 | BC16: 0.0632676 | BD16: -0.12947515 | BE16: 0.09832163 | BF16: -0.12156956 | BG16: 0.27264518 | BH16: 0.0599899 | BI16: 0.22540316 | BJ16: 0.07865196 | BK16: 0.15493454 | BL16: 0.10684665 | BM16: -0.006783231 | BN16: 0.10635906 | BO16: 0.09914439 | BP16: 0.058701713 | BQ16: 0.0088161025 | BR16: 0.12947392 | BS16: 0.090848744 | BT16: 0.26481152 | BU16: 0.21408503 | BV16: 0.021710932 | BW16: 0.022532564 | BX16: 0.46171218 | BY16: 0.032052096 | BZ16: 0.016084988 | CA16: 0.2368524 | CB16: 0.22169179 | CC16: 0.22586815 | CD16: 0.15603358 | CE16: 0.17956896 | CF16: 0.07952938 | CG16: 0.2568253 | CH16: 0.09188079 | CI16: -0.00259538 | CJ16: 0.2268815 | CK16: 0.1275821 | CL16: 0.083514504 | CM16: 0.13846946 | CN16: 0.036648326 | CO16: -0.06458057 | CP16: 0.2710207 | CQ16: 0.16433547 | CR16: 0.17626375 | CS16: 0.31093937 | CT16: 0.21519637 | CU16: 0.006147517 | CV16: 0.20728184 | CW16: 0.06422042 | CX16: 0.18210475 | CY16: 0.2933408 | CZ16: 0.20038849 | DA16: 0.037975013 | DB16: 0.034804244 | DC16: 0.9694577 | DD16: 0.32522467 | DE16: 0.17253937 | DF16: =AVERAGE(D16:J16,L16:AY16,BA16:DB16,DD16:DE16) -> 0.12804424 | DG16: =IF(DF16>=0.25,1,0) -> 0 | DH16: 0 | DI16: =VLOOKUP(B16,owner_jaccard!$C$1:$E$1128,3,FALSE) -> 0.13157895 | DJ16: =VLOOKUP(B16,partic_jaccard!$C$1:$E$1128,3,FALSE) -> 0.3 | DK16: =VLOOKUP(B16,rtword_jaccard!$C$1:$E$1128,3,FALSE) -> 0.13636364 | DL16: =VLOOKUP(B16,rtword_jaccard!$C$1:$F$1128,4,FALSE) -> 0.17647059 | DM16: =VLOOKUP(B16,rtword_jaccard!$C$1:$G$1128,5,FALSE) -> 0.18577075 | DN16: =VLOOKUP(B16,owner_j_重み付き!$C$1:$E$1128,3) -> 0.0032 | DO16: =VLOOKUP(B16,part_j_重み付き!$C$1:$E$1128,3,FALSE) -> 0.0223 | DP16: =VLOOKUP(B16,journalsection_jaccard!$C$2:$E$1129,3,FALSE) -> 0.42857143 | DQ16: =VLOOKUP(B16,journalsection_jaccard!$C$2:$F$1129,4,FALSE) -> 0.29032258 | DR16: =VLOOKUP(B16,journalsection_jaccard!$C$2:$G$1129,5,FALSE) -> 0.25 | DS16: =VLOOKUP(B16,journalsection_jaccard!$C$2:$H$1129,6,FALSE) -> 0.11111111
A17: 10 | B17: Artificial Intelligence vs Cellular Neuroscience | C17: 人工知能と細胞神経科学の最先端 | D17: 0.12808733 | E17: 0.18284601 | F17: -0.022274047 | G17: 0.30595422 | H17: 0.17047858 | I17: -0.11967152 | J17: 0.22343233 | K17: 0.97843456 | L17: 0.0368001 | M17: 0.1246935 | N17: 0.28139275 | O17: 0.078469954 | P17: 0.06800611 | Q17: 0.24381158 | R17: 0.011143997 | S17: 0.32257104 | T17: 0.26345372 | U17: 0.10002839 | V17: -0.11708163 | W17: 0.2189618 | X17: 0.17084791 | Y17: 0.059773907 | Z17: 0.14358091 | AA17: -0.18829879 | AB17: 0.14481144 | AC17: 0.3162298 | AD17: 0.1579428 | AE17: 0.18275186 | AF17: 0.23183429 | AG17: 0.06835698 | AH17: 0.04189499 | AI17: 0.06867632 | AJ17: 0.12744565 | AK17: 0.26136133 | AL17: 0.28465512 | AM17: 0.2266159 | AN17: 0.044420324 | AO17: 0.0756609 | AP17: 0.22144662 | AQ17: 0.28446698 | AR17: 0.1100195 | AS17: 0.14638016 | AT17: -0.017436106 | AU17: 0.10856025 | AV17: 0.017693458 | AW17: 0.28369883 | AX17: 0.055762686 | AY17: 0.2774268 | AZ17: 0.95559126 | BA17: 0.14639519 | BB17: 0.07808223 | BC17: 0.15367183 | BD17: 0.024508353 | BE17: 0.15707786 | BF17: 0.06066297 | BG17: 0.12014665 | BH17: -0.020819848 | BI17: 0.213879 | BJ17: 0.2412934 | BK17: 0.3372256 | BL17: 0.023261804 | BM17: 0.18875974 | BN17: 0.015198481 | BO17: 0.2909385 | BP17: 0.037339073 | BQ17: 0.16489282 | BR17: 0.1816038 | BS17: 0.11090946 | BT17: 0.21094222 | BU17: 0.14440936 | BV17: 0.14563346 | BW17: 0.23204054 | BX17: 0.33441025 | BY17: 0.13100581 | BZ17: 0.15645546 | CA17: 0.14438772 | CB17: 0.30878526 | CC17: 0.17931893 | CD17: 0.15452035 | CE17: 0.26561037 | CF17: 0.28920168 | CG17: 0.16751356 | CH17: 0.13302805 | CI17: 0.059588425 | CJ17: 0.13811392 | CK17: 0.01898865 | CL17: 0.10776478 | CM17: 0.09711278 | CN17: -0.0069855456 | CO17: -0.05878933 | CP17: 0.16184558 | CQ17: 0.21156354 | CR17: 0.26484632 | CS17: 0.2875418 | CT17: 0.0066935816 | CU17: 0.05982157 | CV17: 0.24941435 | CW17: -0.033184916 | CX17: 0.01814666 | CY17: 0.2754997 | CZ17: 0.1800981 | DA17: 0.22492217 | DB17: 0.17118031 | DC17: 0.95072407 | DD17: 0.15953991 | DE17: -0.01631847 | DF17: =AVERAGE(D17:J17,L17:AY17,BA17:DB17,DD17:DE17) -> 0.14084834 | DG17: =IF(DF17>=0.25,1,0) -> 0 | DH17: 0.00070109839 | DI17: =VLOOKUP(B17,owner_jaccard!$C$1:$E$1128,3,FALSE) -> 0.24324324 | DJ17: =VLOOKUP(B17,partic_jaccard!$C$1:$E$1128,3,FALSE) -> 0.24 | DK17: =VLOOKUP(B17,rtword_jaccard!$C$1:$E$1128,3,FALSE) -> 0.086956522 | DL17: =VLOOKUP(B17,rtword_jaccard!$C$1:$F$1128,4,FALSE) -> 0.15606936 | DM17: =VLOOKUP(B17,rtword_jaccard!$C$1:$G$1128,5,FALSE) -> 0.19047619 | DN17: =VLOOKUP(B17,owner_j_重み付き!$C$1:$E$1128,3) -> 0.003 | DO17: =VLOOKUP(B17,part_j_重み付き!$C$1:$E$1128,3,FALSE) -> 0.0312 | DP17: =VLOOKUP(B17,journalsection_jaccard!$C$2:$E$1129,3,FALSE) -> 0.26582278 | DQ17: =VLOOKUP(B17,journalsection_jaccard!$C$2:$F$1129,4,FALSE) -> 0.33333333 | DR17: =VLOOKUP(B17,journalsection_jaccard!$C$2:$G$1129,5,FALSE) -> 0.23966942 | DS17: =VLOOKUP(B17,journalsection_jaccard!$C$2:$H$1129,6,FALSE) -> 0.063829787
A18: 11 | B18: Artificial Intelligence vs Cellular and Infection Microbiology | C18: 人工知能と細胞および感染微生物学の最先端 | D18: 0.18342178 | E18: 0.1897683 | F18: 0.002922522 | G18: 0.23289147 | H18: 0.057013247 | I18: -0.04566499 | J18: 0.31457862 | K18: 0.9751173 | L18: 0.15489027 | M18: 0.13083914 | N18: 0.27575642 | O18: -0.0787008 | P18: 0.13453792 | Q18: 0.11554273 | R18: -0.07524838 | S18: 0.0749717 | T18: 0.037165295 | U18: 0.044952344 | V18: 0.008605208 | W18: 0.13808335 | X18: 0.10167003 | Y18: 0.063262284 | Z18: 0.04045021 | AA18: 0.011182852 | AB18: -0.040267687 | AC18: 0.31398174 | AD18: -0.047235306 | AE18: 0.038877305 | AF18: 0.08255166 | AG18: -0.010776321 | AH18: -0.08585999 | AI18: 0.21668349 | AJ18: -0.0039800443 | AK18: 0.19463748 | AL18: 0.050730184 | AM18: 0.31335768 | AN18: 0.0055017965 | AO18: 0.05118811 | AP18: 0.16342428 | AQ18: 0.14312081 | AR18: 0.18945815 | AS18: 0.061313313 | AT18: 0.10540165 | AU18: 0.15180744 | AV18: -0.12677403 | AW18: 0.26836312 | AX18: 0.041222595 | AY18: 0.264921 | AZ18: 0.9528046 | BA18: 0.09434747 | BB18: 0.10266551 | BC18: 0.23842762 | BD18: 0.0019189 | BE18: 0.20237793 | BF18: 0.16151737 | BG18: 0.23064317 | BH18: 0.00010919049 | BI18: 0.21225765 | BJ18: 0.19732837 | BK18: 0.18651646 | BL18: 0.18667647 | BM18: 0.21647128 | BN18: 0.097042754 | BO18: 0.23967317 | BP18: 0.14653187 | BQ18: 0.19463816 | BR18: -0.012650452 | BS18: 0.19470964 | BT18: 0.34320667 | BU18: 0.115197 | BV18: 0.06392746 | BW18: 0.16478652 | BX18: 0.43716386 | BY18: 0.07977297 | BZ18: 0.07481207 | CA18: 0.038197443 | CB18: 0.26080576 | CC18: 0.31913674 | CD18: 0.20718254 | CE18: 0.244191 | CF18: 0.22295773 | CG18: 0.14286838 | CH18: 0.1471669 | CI18: 0.13638213 | CJ18: 0.28995955 | CK18: 0.21179155 | CL18: 0.07520988 | CM18: 0.0955561 | CN18: 0.10349715 | CO18: 0.11526085 | CP18: 0.17212479 | CQ18: 0.10601029 | CR18: 0.2747634 | CS18: 0.21397819 | CT18: 0.0514632 | CU18: 0.043480143 | CV18: 0.13850799 | CW18: 0.11598287 | CX18: 0.11918014 | CY18: 0.24563432 | CZ18: 0.33897698 | DA18: 0.16689406 | DB18: 0.09741924 | DC18: 0.97528553 | DD18: 0.13731009 | DE18: 0.050831173 | DF18: =AVERAGE(D18:J18,L18:AY18,BA18:DB18,DD18:DE18) -> 0.13113912 | DG18: =IF(DF18>=0.25,1,0) -> 0 | DH18: 0 | DI18: =VLOOKUP(B18,owner_jaccard!$C$1:$E$1128,3,FALSE) -> 0.25 | DJ18: =VLOOKUP(B18,partic_jaccard!$C$1:$E$1128,3,FALSE) -> 0.27586207 | DK18: =VLOOKUP(B18,rtword_jaccard!$C$1:$E$1128,3,FALSE) -> 0.11111111 | DL18: =VLOOKUP(B18,rtword_jaccard!$C$1:$F$1128,4,FALSE) -> 0.16959064 | DM18: =VLOOKUP(B18,rtword_jaccard!$C$1:$G$1128,5,FALSE) -> 0.18110236 | DN18: =VLOOKUP(B18,owner_j_重み付き!$C$1:$E$1128,3) -> 0.0039 | DO18: =VLOOKUP(B18,part_j_重み付き!$C$1:$E$1128,3,FALSE) -> 0.0578 | DP18: =VLOOKUP(B18,journalsection_jaccard!$C$2:$E$1129,3,FALSE) -> 0.42857143 | DQ18: =VLOOKUP(B18,journalsection_jaccard!$C$2:$F$1129,4,FALSE) -> 0.34228188 | DR18: =VLOOKUP(B18,journalsection_jaccard!$C$2:$G$1129,5,FALSE) -> 0.28755365 | DS18: =VLOOKUP(B18,journalsection_jaccard!$C$2:$H$1129,6,FALSE) -> 0.13636364
A19: 12 | B19: Artificial Intelligence vs Chemistry | C19: 人工知能と化学の最先端 | D19: 0.1378659 | E19: 0.038918514 | F19: 0.044691253 | G19: 0.03503161 | H19: 0.15545493 | I19: 0.094398946 | J19: 0.030910434 | K19: 0.9758601 | L19: 0.038377564 | M19: 0.23345198 | N19: 0.11421958 | O19: 0.12292471 | P19: -0.019427557 | Q19: 0.27118137 | R19: 0.09477604 | S19: 0.20461287 | T19: 0.37285173 | U19: 0.10903147 | V19: 0.17414518 | W19: 0.15874985 | X19: 0.1980999 | Y19: 0.08183932 | Z19: 0.022953896 | AA19: -0.05618257 | AB19: 0.25967172 | AC19: 0.23240463 | AD19: 0.22001792 | AE19: 0.138259 | AF19: 0.21202828 | AG19: 0.27545613 | AH19: 0.10628339 | AI19: 0.42305166 | AJ19: 0.14908361 | AK19: 0.24764457 | AL19: 0.17207274 | AM19: 0.28522956 | AN19: 0.11954443 | AO19: 0.018334921 | AP19: 0.17989495 | AQ19: 0.15800248 | AR19: 0.13033089 | AS19: 0.052905504 | AT19: 0.10917381 | AU19: -0.056616984 | AV19: 0.13959397 | AW19: 0.16092813 | AX19: 0.14718997 | AY19: 0.1743882 | AZ19: 0.9590073 | BA19: 0.04948229 | BB19: 0.092920534 | BC19: 0.28877178 | BD19: 0.0678014 | BE19: 0.18135871 | BF19: 0.13577366 | BG19: 0.21602254 | BH19: -0.03053419 | BI19: 0.14438754 | BJ19: 0.16433415 | BK19: 0.3090691 | BL19: 0.010757414 | BM19: 0.12300831 | BN19: 0.078935415 | BO19: 0.2030101 | BP19: 0.24273601 | BQ19: 0.23018648 | BR19: 0.0595755 | BS19: 0.043071147 | BT19: 0.13880926 | BU19: 0.13473946 | BV19: 0.08143832 | BW19: 0.12712325 | BX19: 0.23742358 | BY19: 0.29712704 | BZ19: 0.0387075 | CA19: 0.37764966 | CB19: 0.24568433 | CC19: 0.23588486 | CD19: 0.10337529 | CE19: 0.15588018 | CF19: 0.20893393 | CG19: 0.3351706 | CH19: 0.05302983 | CI19: 0.17129163 | CJ19: 0.24740338 | CK19: 0.24056973 | CL19: 0.12856753 | CM19: 0.12163554 | CN19: 0.017068684 | CO19: 0.16610724 | CP19: 0.15613121 | CQ19: 0.22080508 | CR19: 0.18030132 | CS19: 0.12198893 | CT19: 0.12334359 | CU19: 0.19363232 | CV19: 0.30101365 | CW19: -0.11812254 | CX19: 0.1355971 | CY19: 0.31265342 | CZ19: 0.14469506 | DA19: 0.1355545 | DB19: 0.14681084 | DC19: 0.96192914 | DD19: 0.076983355 | DE19: 0.07533252 | DF19: =AVERAGE(D19:J19,L19:AY19,BA19:DB19,DD19:DE19) -> 0.14946368 | DG19: =IF(DF19>=0.25,1,0) -> 0 | DH19: 0 | DI19: =VLOOKUP(B19,owner_jaccard!$C$1:$E$1128,3,FALSE) -> 0.15 | DJ19: =VLOOKUP(B19,partic_jaccard!$C$1:$E$1128,3,FALSE) -> 0.2962963 | DK19: =VLOOKUP(B19,rtword_jaccard!$C$1:$E$1128,3,FALSE) -> 0.17647059 | DL19: =VLOOKUP(B19,rtword_jaccard!$C$1:$F$1128,4,FALSE) -> 0.22699387 | DM19: =VLOOKUP(B19,rtword_jaccard!$C$1:$G$1128,5,FALSE) -> 0.2295082 | DN19: =VLOOKUP(B19,owner_j_重み付き!$C$1:$E$1128,3) -> 0.0051 | DO19: =VLOOKUP(B19,part_j_重み付き!$C$1:$E$1128,3,FALSE) -> 0.0647 | DP19: =VLOOKUP(B19,journalsection_jaccard!$C$2:$E$1129,3,FALSE) -> 0.5625 | DQ19: =VLOOKUP(B19,journalsection_jaccard!$C$2:$F$1129,4,FALSE) -> 0.38888889 | DR19: =VLOOKUP(B19,journalsection_jaccard!$C$2:$G$1129,5,FALSE) -> 0.36986301 | DS19: =VLOOKUP(B19,journalsection_jaccard!$C$2:$H$1129,6,FALSE) -> 0.19047619
A20: 13 | B20: Artificial Intelligence vs Communication | C20: 人工知能とコミュニケーションのフロンティア | D20: 0.18890165 | E20: 0.29145536 | F20: 0.04650585 | G20: 0.12719616 | H20: 0.28374 | I20: 0.06382006 | J20: 0.20769879 | K20: 0.98085827 | L20: 0.3549056 | M20: 0.20323354 | N20: 0.26788187 | O20: 0.031019274 | P20: 0.11679357 | Q20: 0.33676276 | R20: 0.050642934 | S20: -0.06355832 | T20: 0.26860374 | U20: 0.25967202 | V20: 0.14478996 | W20: 0.080091774 | X20: 0.07097017 | Y20: 0.10096227 | Z20: 0.061625857 | AA20: 0.0804054 | AB20: 0.24086525 | AC20: 0.4536813 | AD20: 0.19735503 | AE20: 0.27101102 | AF20: 0.30037242 | AG20: 0.24745288 | AH20: 0.00618108 | AI20: 0.2956121 | AJ20: 0.2770229 | AK20: 0.072708875 | AL20: 0.12178624 | AM20: 0.3739388 | AN20: 0.23108453 | AO20: 0.25709176 | AP20: 0.24842654 | AQ20: 0.35281596 | AR20: 0.32606676 | AS20: 0.1215032 | AT20: 0.0314882 | AU20: 0.10026281 | AV20: 0.31510738 | AW20: 0.13128594 | AX20: 0.07780433 | AY20: 0.3509864 | AZ20: 0.94208455 | BA20: -0.010845103 | BB20: 0.261309 | BC20: 0.3789818 | BD20: 0.25265053 | BE20: 0.25490308 | BF20: 0.10204894 | BG20: 0.15965416 | BH20: 0.14473632 | BI20: 0.25977325 | BJ20: 0.22404712 | BK20: 0.38003218 | BL20: -0.0018039959 | BM20: 0.16270156 | BN20: 0.19685477 | BO20: 0.28977415 | BP20: 0.18618362 | BQ20: 0.17326877 | BR20: 0.08859496 | BS20: 0.16617647 | BT20: 0.37139946 | BU20: 0.26321432 | BV20: 0.13003795 | BW20: 0.17265081 | BX20: 0.2948767 | BY20: 0.18552539 | BZ20: 0.37067088 | CA20: 0.14660287 | CB20: 0.3609688 | CC20: 0.21085553 | CD20: 0.11311556 | CE20: 0.2864832 | CF20: 0.21436284 | CG20: 0.19826996 | CH20: 0.074973375 | CI20: 0.28736162 | CJ20: 0.23059702 | CK20: 0.09180633 | CL20: 0.26353952 | CM20: 0.23379268 | CN20: 0.480491 | CO20: 0.15915969 | CP20: 0.38694745 | CQ20: 0.3299997 | CR20: 0.34490457 | CS20: 0.28333953 | CT20: 0.31045383 | CU20: 0.16907792 | CV20: 0.28428468 | CW20: 0.09961524 | CX20: 0.24712566 | CY20: 0.15468088 | CZ20: 0.21988359 | DA20: 0.14843369 | DB20: 0.24490376 | DC20: 0.9629676 | DD20: 0.17308994 | DE20: -0.020556785 | DF20: =AVERAGE(D20:J20,L20:AY20,BA20:DB20,DD20:DE20) -> 0.20545643 | DG20: =IF(DF20>=0.25,1,0) -> 0 | DH20: 0.0070323488 | DI20: =VLOOKUP(B20,owner_jaccard!$C$1:$E$1128,3,FALSE) -> 0.26086957 | DJ20: =VLOOKUP(B20,partic_jaccard!$C$1:$E$1128,3,FALSE) -> 0.25925926 | DK20: =VLOOKUP(B20,rtword_jaccard!$C$1:$E$1128,3,FALSE) -> 0.26582278 | DL20: =VLOOKUP(B20,rtword_jaccard!$C$1:$F$1128,4,FALSE) -> 0.28205128 | DM20: =VLOOKUP(B20,rtword_jaccard!$C$1:$G$1128,5,FALSE) -> 0.31004367 | DN20: =VLOOKUP(B20,owner_j_重み付き!$C$1:$E$1128,3) -> 0.0139 | DO20: =VLOOKUP(B20,part_j_重み付き!$C$1:$E$1128,3,FALSE) -> 0.0771 | DP20: =VLOOKUP(B20,journalsection_jaccard!$C$2:$E$1129,3,FALSE) -> 0.63934426 | DQ20: =VLOOKUP(B20,journalsection_jaccard!$C$2:$F$1129,4,FALSE) -> 0.3986014 | DR20: =VLOOKUP(B20,journalsection_jaccard!$C$2:$G$1129,5,FALSE) -> 0.38248848 | DS20: =VLOOKUP(B20,journalsection_jaccard!$C$2:$H$1129,6,FALSE) -> 0.20481928
A21: 14 | B21: Artificial Intelligence vs Digital Health | C21: 人工知能とデジタルヘルスの最先端 | D21: 0.10053545 | E21: -0.055145293 | F21: 0.153752 | G21: 0.06941861 | H21: -0.022139227 | I21: 0.21439946 | J21: 0.064268276 | K21: 0.9826873 | L21: 0.16386908 | M21: 0.26314452 | N21: 0.27543846 | O21: 0.08659997 | P21: 0.19328043 | Q21: 0.28261107 | R21: 0.06177106 | S21: -0.13032673 | T21: 0.3184741 | U21: 0.21074037 | V21: 0.25675237 | W21: 0.13251145 | X21: 0.01901421 | Y21: 0.14516373 | Z21: 0.11655489 | AA21: -0.03599735 | AB21: 0.18580224 | AC21: 0.24085262 | AD21: 0.2428136 | AE21: 0.19379263 | AF21: 0.23966047 | AG21: 0.50010633 | AH21: 0.018873729 | AI21: 0.24248788 | AJ21: 0.075243436 | AK21: 0.14658251 | AL21: 0.20508558 | AM21: 0.24989673 | AN21: 0.13009852 | AO21: 0.26151666 | AP21: 0.36048108 | AQ21: 0.22932291 | AR21: 0.35586834 | AS21: 0.032047506 | AT21: -0.15175535 | AU21: 0.1386028 | AV21: 0.057082534 | AW21: 0.1432633 | AX21: 0.17275316 | AY21: 0.30531523 | AZ21: 0.95553297 | BA21: 0.1200805 | BB21: 0.24951513 | BC21: -0.004035425 | BD21: 0.3149857 | BE21: 0.10408397 | BF21: 0.16657655 | BG21: 0.25112566 | BH21: 0.06416209 | BI21: 0.33072624 | BJ21: 0.22132315 | BK21: 0.39514148 | BL21: 0.055433434 | BM21: 0.11890394 | BN21: 0.359215 | BO21: 0.29256514 | BP21: 0.27419278 | BQ21: 0.15382724 | BR21: 0.06444584 | BS21: 0.23231976 | BT21: 0.13526073 | BU21: 0.08320285 | BV21: 0.11041538 | BW21: 0.058383998 | BX21: 0.20095286 | BY21: 0.11290674 | BZ21: 0.1540398 | CA21: 0.11776859 | CB21: 0.3204879 | CC21: 0.26284647 | CD21: 0.25901604 | CE21: 0.24139565 | CF21: 0.01917721 | CG21: 0.35013798 | CH21: 0.082944565 | CI21: 0.442754 | CJ21: 0.1722516 | CK21: 0.11793894 | CL21: 0.31265885 | CM21: 0.21470742 | CN21: 0.43866438 | CO21: 0.14136405 | CP21: 0.29948053 | CQ21: 0.08710268 | CR21: 0.18647157 | CS21: 0.10558831 | CT21: 0.06973666 | CU21: 0.1855952 | CV21: 0.44372886 | CW21: 0.13660708 | CX21: 0.24323685 | CY21: 0.38189775 | CZ21: 0.19950674 | DA21: 0.06019276 | DB21: 0.11516593 | DC21: 0.96843916 | DD21: 0.10008495 | DE21: -0.005226903 | DF21: =AVERAGE(D21:J21,L21:AY21,BA21:DB21,DD21:DE21) -> 0.17653901 | DG21: =IF(DF21>=0.25,1,0) -> 0 | DH21: 0.0012658228 | DI21: =VLOOKUP(B21,owner_jaccard!$C$1:$E$1128,3,FALSE) -> 0.32142857 | DJ21: =VLOOKUP(B21,partic_jaccard!$C$1:$E$1128,3,FALSE) -> 0.25925926 | DK21: =VLOOKUP(B21,rtword_jaccard!$C$1:$E$1128,3,FALSE) -> 0.36986301 | DL21: =VLOOKUP(B21,rtword_jaccard!$C$1:$F$1128,4,FALSE) -> 0.41843972 | DM21: =VLOOKUP(B21,rtword_jaccard!$C$1:$G$1128,5,FALSE) -> 0.44230769 | DN21: =VLOOKUP(B21,owner_j_重み付き!$C$1:$E$1128,3) -> 0.02 | DO21: =VLOOKUP(B21,part_j_重み付き!$C$1:$E$1128,3,FALSE) -> 0.14 | DP21: =VLOOKUP(B21,journalsection_jaccard!$C$2:$E$1129,3,FALSE) -> 0.51515152 | DQ21: =VLOOKUP(B21,journalsection_jaccard!$C$2:$F$1129,4,FALSE) -> 0.43884892 | DR21: =VLOOKUP(B21,journalsection_jaccard!$C$2:$G$1129,5,FALSE) -> 0.33928571 | DS21: =VLOOKUP(B21,journalsection_jaccard!$C$2:$H$1129,6,FALSE) -> 0.28205128
A22: 15 | B22: Artificial Intelligence vs Earth Science | C22: 人工知能と地球科学の最先端 | D22: 0.32885474 | E22: 0.17806923 | F22: 0.18577449 | G22: 0.26127335 | H22: 0.06412143 | I22: 0.14277905 | J22: 0.28045082 | K22: 0.9776057 | L22: 0.16955502 | M22: 0.20008527 | N22: 0.10593998 | O22: 0.07918127 | P22: 0.09242069 | Q22: 0.21496269 | R22: 0.08016634 | S22: 0.12590228 | T22: 0.17225996 | U22: 0.34116954 | V22: 0.06855043 | W22: 0.22207665 | X22: 0.36947763 | Y22: 0.11091036 | Z22: 0.10336591 | AA22: 0.03293886 | AB22: 0.13059501 | AC22: 0.28136522 | AD22: 0.21721554 | AE22: -0.068254344 | AF22: 0.2931098 | AG22: 0.2884769 | AH22: 0.29424736 | AI22: 0.24798836 | AJ22: 0.19555023 | AK22: 0.20278387 | AL22: 0.19410203 | AM22: 0.2857124 | AN22: 0.16145897 | AO22: 0.19899674 | AP22: 0.074394606 | AQ22: 0.28050658 | AR22: 0.17356902 | AS22: 0.12074686 | AT22: 0.068983845 | AU22: 0.06800106 | AV22: 0.1180484 | AW22: 0.19809844 | AX22: 0.08356691 | AY22: 0.3087325 | AZ22: 0.95662695 | BA22: 0.14311528 | BB22: 0.03284772 | BC22: 0.34308156 | BD22: 0.1212858 | BE22: 0.12496768 | BF22: 0.2667395 | BG22: -0.00405095 | BH22: -0.07665005 | BI22: 0.22464877 | BJ22: 0.24462338 | BK22: 0.18485326 | BL22: 0.23346892 | BM22: 0.22306189 | BN22: 0.15220372 | BO22: 0.17798682 | BP22: 0.26565927 | BQ22: 0.1444228 | BR22: -0.04060472 | BS22: 0.12535836 | BT22: 0.2965203 | BU22: 0.24850552 | BV22: 0.073194385 | BW22: 0.14575036 | BX22: 0.32871112 | BY22: 0.048721258 | BZ22: 0.14211103 | CA22: 0.23763019 | CB22: 0.23738834 | CC22: 0.30458233 | CD22: 0.23346208 | CE22: 0.2223624 | CF22: 0.16029319 | CG22: 0.19561687 | CH22: 0.16966072 | CI22: 0.07472849 | CJ22: 0.13905546 | CK22: 0.22078176 | CL22: 0.17274787 | CM22: 0.06482942 | CN22: 0.22476824 | CO22: 0.13310345 | CP22: 0.18917671 | CQ22: 0.12750679 | CR22: 0.20708407 | CS22: 0.06938652 | CT22: 0.22989121 | CU22: 0.0031079464 | CV22: 0.08946118 | CW22: 0.060942408 | CX22: 0.20460744 | CY22: 0.12457978 | CZ22: 0.28266883 | DA22: 0.16973795 | DB22: 0.24068472 | DC22: 0.96334034 | DD22: 0.31138194 | DE22: 0.011199646 | DF22: =AVERAGE(D22:J22,L22:AY22,BA22:DB22,DD22:DE22) -> 0.17117712 | DG22: =IF(DF22>=0.25,1,0) -> 0 | DH22: 0 | DI22: =VLOOKUP(B22,owner_jaccard!$C$1:$E$1128,3,FALSE) -> 0.09375 | DJ22: =VLOOKUP(B22,partic_jaccard!$C$1:$E$1128,3,FALSE) -> 0.16 | DK22: =VLOOKUP(B22,rtword_jaccard!$C$1:$E$1128,3,FALSE) -> 0.25 | DL22: =VLOOKUP(B22,rtword_jaccard!$C$1:$F$1128,4,FALSE) -> 0.22699387 | DM22: =VLOOKUP(B22,rtword_jaccard!$C$1:$G$1128,5,FALSE) -> 0.24481328 | DN22: =VLOOKUP(B22,owner_j_重み付き!$C$1:$E$1128,3) -> 0.002 | DO22: =VLOOKUP(B22,part_j_重み付き!$C$1:$E$1128,3,FALSE) -> 0.0163 | DP22: =VLOOKUP(B22,journalsection_jaccard!$C$2:$E$1129,3,FALSE) -> 0.44927536 | DQ22: =VLOOKUP(B22,journalsection_jaccard!$C$2:$F$1129,4,FALSE) -> 0.34228188 | DR22: =VLOOKUP(B22,journalsection_jaccard!$C$2:$G$1129,5,FALSE) -> 0.32743363 | DS22: =VLOOKUP(B22,journalsection_jaccard!$C$2:$H$1129,6,FALSE) -> 0.11111111
A23: 16 | B23: Artificial Intelligence vs Ecology and Evolution | C23: 人工知能と生態学と進化のフロンティア | D23: 0.20039855 | E23: 0.20314436 | F23: 0.17224275 | G23: 0.27017114 | H23: 0.2826039 | I23: -0.011166667 | J23: 0.28125152 | K23: 0.97642523 | L23: 0.1923145 | M23: 0.13985595 | N23: 0.33411944 | O23: 0.047112904 | P23: 0.26413327 | Q23: 0.2830915 | R23: 0.11762932 | S23: -0.035211008 | T23: 0.2533425 | U23: 0.25998482 | V23: 0.05703334 | W23: 0.25735918 | X23: 0.18539353 | Y23: 0.3465819 | Z23: 0.05316593 | AA23: 0.16239178 | AB23: 0.20590787 | AC23: 0.32507515 | AD23: 0.21929525 | AE23: 0.049294524 | AF23: 0.27034807 | AG23: 0.019281572 | AH23: 0.10187601 | AI23: 0.3911034 | AJ23: 0.2400171 | AK23: 0.17186865 | AL23: 0.14158213 | AM23: 0.1928649 | AN23: -0.10623241 | AO23: 0.16124877 | AP23: 0.27511021 | AQ23: 0.17642583 | AR23: 0.26576638 | AS23: 0.14346257 | AT23: 0.11040377 | AU23: 0.07281126 | AV23: 0.096080124 | AW23: 0.26948616 | AX23: 0.13718092 | AY23: 0.43338144 | AZ23: 0.962762 | BA23: 0.15611552 | BB23: 0.24533941 | BC23: 0.07452826 | BD23: 0.07307469 | BE23: 0.22198804 | BF23: 0.26860714 | BG23: 0.25765705 | BH23: -0.08988427 | BI23: 0.31020665 | BJ23: 0.21599023 | BK23: 0.13389468 | BL23: 0.0677354 | BM23: 0.280758 | BN23: 0.17219287 | BO23: 0.34198588 | BP23: 0.17117125 | BQ23: 0.18520789 | BR23: -0.10058872 | BS23: 0.28470588 | BT23: 0.20035489 | BU23: 0.19973905 | BV23: 0.17974016 | BW23: 0.13159452 | BX23: 0.3702137 | BY23: 0.14089814 | BZ23: 0.07799965 | CA23: 0.16121577 | CB23: 0.12401138 | CC23: 0.27840978 | CD23: 0.14224385 | CE23: 0.23707053 | CF23: 0.09536341 | CG23: 0.26822823 | CH23: 0.12692294 | CI23: 0.2985948 | CJ23: 0.17676246 | CK23: 0.13951324 | CL23: 0.26155573 | CM23: 0.14669469 | CN23: 0.2553966 | CO23: 0.011209543 | CP23: 0.33689502 | CQ23: 0.16931769 | CR23: 0.4029187 | CS23: 0.33645913 | CT23: 0.29197097 | CU23: -0.12657402 | CV23: 0.1820191 | CW23: 0.16748042 | CX23: 0.16727155 | CY23: 0.21812905 | CZ23: 0.32535192 | DA23: 0.051342487 | DB23: 0.26057944 | DC23: 0.971591 | DD23: 0.21235316 | DE23: 0.092729434 | DF23: =AVERAGE(D23:J23,L23:AY23,BA23:DB23,DD23:DE23) -> 0.18508007 | DG23: =IF(DF23>=0.25,1,0) -> 0 | DH23: 0 | DI23: =VLOOKUP(B23,owner_jaccard!$C$1:$E$1128,3,FALSE) -> 0.17948718 | DJ23: =VLOOKUP(B23,partic_jaccard!$C$1:$E$1128,3,FALSE) -> 0.2 | DK23: =VLOOKUP(B23,rtword_jaccard!$C$1:$E$1128,3,FALSE) -> 0.19047619 | DL23: =VLOOKUP(B23,rtword_jaccard!$C$1:$F$1128,4,FALSE) -> 0.21212121 | DM23: =VLOOKUP(B23,rtword_jaccard!$C$1:$G$1128,5,FALSE) -> 0.25 | DN23: =VLOOKUP(B23,owner_j_重み付き!$C$1:$E$1128,3) -> 0.0078 | DO23: =VLOOKUP(B23,part_j_重み付き!$C$1:$E$1128,3,FALSE) -> 0.03 | DP23: =VLOOKUP(B23,journalsection_jaccard!$C$2:$E$1129,3,FALSE) -> 0.26582278 | DQ23: =VLOOKUP(B23,journalsection_jaccard!$C$2:$F$1129,4,FALSE) -> 0.27388535 | DR23: =VLOOKUP(B23,journalsection_jaccard!$C$2:$G$1129,5,FALSE) -> 0.27118644 | DS23: =VLOOKUP(B23,journalsection_jaccard!$C$2:$H$1129,6,FALSE) -> 0.063829787
... A55: 48 | B55: Computer Science vs Psychology | C55: コンピュータサイエンス vs 心理学 | D55: 0.05032115 | E55: -0.006511974 | F55: 0.09261271 | G55: 0.14127353 | H55: 0.024073452 | I55: -0.03424213 | J55: 0.02125021 | K55: 0.98681945 | L55: -0.063864306 | M55: 0.12244655 | N55: 0.25964284 | O55: 0.07860828 | P55: -0.004127651 | Q55: 0.25330165 | R55: 0.0930247 | S55: -0.05205575 | T55: 0.20160392 | U55: 0.16573735 | V55: 0.06104762 | W55: 0.057228647 | X55: 0.15858452 | Y55: 0.08259598 | Z55: 0.22902068 | AA55: 0.027992833 | AB55: 0.21710803 | AC55: 0.066966094 | AD55: 0.09628588 | AE55: 0.26231322 | AF55: 0.21931562 | AG55: 0.17264007 | AH55: 0.16259617 | AI55: 0.2666285 | AJ55: 0.27117306 | AK55: 0.17972887 | AL55: 0.13591108 | AM55: 0.043693583 | AN55: 0.14533924 | AO55: 0.04652708 | AP55: 0.14394633 | AQ55: 0.172623 | AR55: 0.19957462 | AS55: 0.1350417 | AT55: 0.22602369 | AU55: 0.17453933 | AV55: 0.08990819 | AW55: 0.14333552 | AX55: 0.11165532 | AY55: 0.10163294 | AZ55: 0.9630468 | BA55: 0.05633061 | BB55: 0.23604183 | BC55: 0.027157623 | BD55: 0.15601411 | BE55: 0.087609895 | BF55: 0.3197219 | BG55: 0.16238777 | BH55: 0.15925309 | BI55: 0.19443856 | BJ55: 0.14738648 | BK55: 0.23127158 | BL55: 0.09749685 | BM55: 0.14286874 | BN55: 0.011248066 | BO55: 0.21345913 | BP55: 0.23498929 | BQ55: -0.20244186 | BR55: 0.22462504 | BS55: 0.21742113 | BT55: 0.3511752 | BU55: 0.050319582 | BV55: 0.22490983 | BW55: 0.14124238 | BX55: 0.35361516 | BY55: 0.04898981 | BZ55: 0.08860954 | CA55: 0.015785862 | CB55: 0.22242725 | CC55: 0.2869039 | CD55: 0.3677837 | CE55: 0.22041167 | CF55: 0.27731413 | CG55: 0.14361264 | CH55: 0.3198907 | CI55: 0.21679172 | CJ55: 0.3548644 | CK55: 0.20327355 | CL55: 0.30551547 | CM55: 0.22600913 | CN55: 0.18040879 | CO55: 0.083816946 | CP55: 0.18410912 | CQ55: -0.0055849836 | CR55: 0.30206564 | CS55: 0.1727033 | CT55: 0.11350852 | CU55: 0.034367286 | CV55: 0.29747623 | CW55: 0.06418494 | CX55: 0.11784209 | CY55: 0.25595814 | CZ55: 0.30576736 | DA55: 0.16092208 | DB55: 0.22877014 | DC55: 0.96760935 | DD55: 0.0400439 | DE55: 0.20698476 | DF55: =AVERAGE(D55:J55,L55:AY55,BA55:DB55,DD55:DE55) -> 0.1516907 | DG55: =IF(DF55>=0.25,1,0) -> 0 | DH55: 0.12109875 | DI55: =VLOOKUP(B55,owner_jaccard!$C$1:$E$1128,3,FALSE) -> 0.31578947 | DJ55: =VLOOKUP(B55,partic_jaccard!$C$1:$E$1128,3,FALSE) -> 0.21875 | DK55: =VLOOKUP(B55,rtword_jaccard!$C$1:$E$1128,3,FALSE) -> 0.20481928 | DL55: =VLOOKUP(B55,rtword_jaccard!$C$1:$F$1128,4,FALSE) -> 0.29032258 | DM55: =VLOOKUP(B55,rtword_jaccard!$C$1:$G$1128,5,FALSE) -> 0.33928571 | DN55: =VLOOKUP(B55,owner_j_重み付き!$C$1:$E$1128,3) -> 0.0069 | DO55: =VLOOKUP(B55,part_j_重み付き!$C$1:$E$1128,3,FALSE) -> 0.001 | DP55: =VLOOKUP(B55,journalsection_jaccard!$C$2:$E$1129,3,FALSE) -> 0.49253731 | DQ55: =VLOOKUP(B55,journalsection_jaccard!$C$2:$F$1129,4,FALSE) -> 0.38888889 | DR55: =VLOOKUP(B55,journalsection_jaccard!$C$2:$G$1129,5,FALSE) -> 0.32743363 | DS55: =VLOOKUP(B55,journalsection_jaccard!$C$2:$H$1129,6,FALSE) -> 0.20481928
